Workbook

Sheet About This Report
A1: About This Report
A3: Sheets in this workbook
A4: League Table - standard standings from every played match.
A5: League Summary - one row per team in league-table order: league position, games played, ranks (1 = best) for goals-for supremacy, goals-conceded supremacy, total goals above expected, xPts delta and market points, plus the number of games with positive and negative xG supremacy. The numbers behind the ranks sit in columns K:O.
A6: Overview - a deliberately narrow at-a-glance summary of each team's core xG/xPts form, sorted by Avg xG Delta (For), best first. Medians, adjusted current form, and a couple of stats already shown elsewhere are left off - see the team tabs and the dedicated grid sheets for the full detail.
A7: xPts Table - teams ranked by season-total xPts Delta (actual deserved points minus what the market expected), highest over-performance first - a "truer" table than the real one below since it's driven by chance quality rather than which chances actually went in.
A8: Dashboard - three league-wide charts (xG Delta For, Supremacy Delta, xPts Actual vs Market) so patterns are visible at a glance instead of scrolling through team tabs.
A9: Data Quality - flags fixtures with missing/negative xG or goals, or suspicious exact-0.00 xG on both sides - a first stop before trusting a given run's numbers.
A10: Match Log - the single master data table: one row per fixture (not per team) with every core stat, and an AutoFilter so you can filter by team/venue without hunting through team tabs.
A11: Home & Away Splits - Total/Home/Away average and median supremacy, and Total/Home/Away goals, for every team.
A12: Supremacy Delta / (Home) / (Away) - match-by-match grids of actual vs. expected xG supremacy, each sorted by its own average, highest first.
A13: Total xG Delta - match-by-match grid of how much higher/lower-scoring each match was than the market expected, sorted by its own average, with a Median column at the end.
... A23: • The Supremacy Delta (Home) / (Away) grids are literal snapshots (computed once, at report-generation time) rather than live formulas like the full-season grid, since a team's home-only matches aren't a contiguous block of rows on its own sheet. Re-run the pipeline to refresh them.

Sheet League Table
A1: Pos | B1: Team | C1: P | D1: W | E1: D | F1: L | G1: GF | H1: GA | I1: GD | J1: Pts
A2: =ROW()-1 | B2: Celtic | C2: =COUNTIF('Results Data'!$B$2:$B$49,$B2)+COUNTIF('Results Data'!$C$2:$C$49,$B2) | D2: =SUMPRODUCT(('Results Data'!$B$2:$B$49=$B2)*('Results Data'!$D$2:$D$49>'Results Data'!$E$2:$E$49))+SUMPRODUCT(('Results Data'!$C$2:$C$49=$B2)*('Results Data'!$E$2:$E$49>'Results Data'!$D$2:$D$49)) | E2: =SUMPRODUCT(('Results Data'!$B$2:$B$49=$B2)*('Results Data'!$D$2:$D$49='Results Data'!$E$2:$E$49))+SUMPRODUCT(('Results Data'!$C$2:$C$49=$B2)*('Results Data'!$E$2:$E$49='Results Data'!$D$2:$D$49)) | F2: =C2-D2-E2 | G2: =SUMIF('Results Data'!$B$2:$B$49,$B2,'Results Data'!$D$2:$D$49)+SUMIF('Results Data'!$C$2:$C$49,$B2,'Results Data'!$E$2:$E$49) | H2: =SUMIF('Results Data'!$B$2:$B$49,$B2,'Results Data'!$E$2:$E$49)+SUMIF('Results Data'!$C$2:$C$49,$B2,'Results Data'!$D$2:$D$49) | I2: =G2-H2 | J2: =D2*3+E2
A3: =ROW()-1 | B3: Rangers | C3: =COUNTIF('Results Data'!$B$2:$B$49,$B3)+COUNTIF('Results Data'!$C$2:$C$49,$B3) | D3: =SUMPRODUCT(('Results Data'!$B$2:$B$49=$B3)*('Results Data'!$D$2:$D$49>'Results Data'!$E$2:$E$49))+SUMPRODUCT(('Results Data'!$C$2:$C$49=$B3)*('Results Data'!$E$2:$E$49>'Results Data'!$D$2:$D$49)) | E3: =SUMPRODUCT(('Results Data'!$B$2:$B$49=$B3)*('Results Data'!$D$2:$D$49='Results Data'!$E$2:$E$49))+SUMPRODUCT(('Results Data'!$C$2:$C$49=$B3)*('Results Data'!$E$2:$E$49='Results Data'!$D$2:$D$49)) | F3: =C3-D3-E3 | G3: =SUMIF('Results Data'!$B$2:$B$49,$B3,'Results Data'!$D$2:$D$49)+SUMIF('Results Data'!$C$2:$C$49,$B3,'Results Data'!$E$2:$E$49) | H3: =SUMIF('Results Data'!$B$2:$B$49,$B3,'Results Data'!$E$2:$E$49)+SUMIF('Results Data'!$C$2:$C$49,$B3,'Results Data'!$D$2:$D$49) | I3: =G3-H3 | J3: =D3*3+E3
A4: =ROW()-1 | B4: Heart of Midlothian | C4: =COUNTIF('Results Data'!$B$2:$B$49,$B4)+COUNTIF('Results Data'!$C$2:$C$49,$B4) | D4: =SUMPRODUCT(('Results Data'!$B$2:$B$49=$B4)*('Results Data'!$D$2:$D$49>'Results Data'!$E$2:$E$49))+SUMPRODUCT(('Results Data'!$C$2:$C$49=$B4)*('Results Data'!$E$2:$E$49>'Results Data'!$D$2:$D$49)) | E4: =SUMPRODUCT(('Results Data'!$B$2:$B$49=$B4)*('Results Data'!$D$2:$D$49='Results Data'!$E$2:$E$49))+SUMPRODUCT(('Results Data'!$C$2:$C$49=$B4)*('Results Data'!$E$2:$E$49='Results Data'!$D$2:$D$49)) | F4: =C4-D4-E4 | G4: =SUMIF('Results Data'!$B$2:$B$49,$B4,'Results Data'!$D$2:$D$49)+SUMIF('Results Data'!$C$2:$C$49,$B4,'Results Data'!$E$2:$E$49) | H4: =SUMIF('Results Data'!$B$2:$B$49,$B4,'Results Data'!$E$2:$E$49)+SUMIF('Results Data'!$C$2:$C$49,$B4,'Results Data'!$D$2:$D$49) | I4: =G4-H4 | J4: =D4*3+E4
A5: =ROW()-1 | B5: Dundee | C5: =COUNTIF('Results Data'!$B$2:$B$49,$B5)+COUNTIF('Results Data'!$C$2:$C$49,$B5) | D5: =SUMPRODUCT(('Results Data'!$B$2:$B$49=$B5)*('Results Data'!$D$2:$D$49>'Results Data'!$E$2:$E$49))+SUMPRODUCT(('Results Data'!$C$2:$C$49=$B5)*('Results Data'!$E$2:$E$49>'Results Data'!$D$2:$D$49)) | E5: =SUMPRODUCT(('Results Data'!$B$2:$B$49=$B5)*('Results Data'!$D$2:$D$49='Results Data'!$E$2:$E$49))+SUMPRODUCT(('Results Data'!$C$2:$C$49=$B5)*('Results Data'!$E$2:$E$49='Results Data'!$D$2:$D$49)) | F5: =C5-D5-E5 | G5: =SUMIF('Results Data'!$B$2:$B$49,$B5,'Results Data'!$D$2:$D$49)+SUMIF('Results Data'!$C$2:$C$49,$B5,'Results Data'!$E$2:$E$49) | H5: =SUMIF('Results Data'!$B$2:$B$49,$B5,'Results Data'!$E$2:$E$49)+SUMIF('Results Data'!$C$2:$C$49,$B5,'Results Data'!$D$2:$D$49) | I5: =G5-H5 | J5: =D5*3+E5
A6: =ROW()-1 | B6: St Johnstone | C6: =COUNTIF('Results Data'!$B$2:$B$49,$B6)+COUNTIF('Results Data'!$C$2:$C$49,$B6) | D6: =SUMPRODUCT(('Results Data'!$B$2:$B$49=$B6)*('Results Data'!$D$2:$D$49>'Results Data'!$E$2:$E$49))+SUMPRODUCT(('Results Data'!$C$2:$C$49=$B6)*('Results Data'!$E$2:$E$49>'Results Data'!$D$2:$D$49)) | E6: =SUMPRODUCT(('Results Data'!$B$2:$B$49=$B6)*('Results Data'!$D$2:$D$49='Results Data'!$E$2:$E$49))+SUMPRODUCT(('Results Data'!$C$2:$C$49=$B6)*('Results Data'!$E$2:$E$49='Results Data'!$D$2:$D$49)) | F6: =C6-D6-E6 | G6: =SUMIF('Results Data'!$B$2:$B$49,$B6,'Results Data'!$D$2:$D$49)+SUMIF('Results Data'!$C$2:$C$49,$B6,'Results Data'!$E$2:$E$49) | H6: =SUMIF('Results Data'!$B$2:$B$49,$B6,'Results Data'!$E$2:$E$49)+SUMIF('Results Data'!$C$2:$C$49,$B6,'Results Data'!$D$2:$D$49) | I6: =G6-H6 | J6: =D6*3+E6
A7: =ROW()-1 | B7: Dundee United | C7: =COUNTIF('Results Data'!$B$2:$B$49,$B7)+COUNTIF('Results Data'!$C$2:$C$49,$B7) | D7: =SUMPRODUCT(('Results Data'!$B$2:$B$49=$B7)*('Results Data'!$D$2:$D$49>'Results Data'!$E$2:$E$49))+SUMPRODUCT(('Results Data'!$C$2:$C$49=$B7)*('Results Data'!$E$2:$E$49>'Results Data'!$D$2:$D$49)) | E7: =SUMPRODUCT(('Results Data'!$B$2:$B$49=$B7)*('Results Data'!$D$2:$D$49='Results Data'!$E$2:$E$49))+SUMPRODUCT(('Results Data'!$C$2:$C$49=$B7)*('Results Data'!$E$2:$E$49='Results Data'!$D$2:$D$49)) | F7: =C7-D7-E7 | G7: =SUMIF('Results Data'!$B$2:$B$49,$B7,'Results Data'!$D$2:$D$49)+SUMIF('Results Data'!$C$2:$C$49,$B7,'Results Data'!$E$2:$E$49) | H7: =SUMIF('Results Data'!$B$2:$B$49,$B7,'Results Data'!$E$2:$E$49)+SUMIF('Results Data'!$C$2:$C$49,$B7,'Results Data'!$D$2:$D$49) | I7: =G7-H7 | J7: =D7*3+E7
A8: =ROW()-1 | B8: St Mirren | C8: =COUNTIF('Results Data'!$B$2:$B$49,$B8)+COUNTIF('Results Data'!$C$2:$C$49,$B8) | D8: =SUMPRODUCT(('Results Data'!$B$2:$B$49=$B8)*('Results Data'!$D$2:$D$49>'Results Data'!$E$2:$E$49))+SUMPRODUCT(('Results Data'!$C$2:$C$49=$B8)*('Results Data'!$E$2:$E$49>'Results Data'!$D$2:$D$49)) | E8: =SUMPRODUCT(('Results Data'!$B$2:$B$49=$B8)*('Results Data'!$D$2:$D$49='Results Data'!$E$2:$E$49))+SUMPRODUCT(('Results Data'!$C$2:$C$49=$B8)*('Results Data'!$E$2:$E$49='Results Data'!$D$2:$D$49)) | F8: =C8-D8-E8 | G8: =SUMIF('Results Data'!$B$2:$B$49,$B8,'Results Data'!$D$2:$D$49)+SUMIF('Results Data'!$C$2:$C$49,$B8,'Results Data'!$E$2:$E$49) | H8: =SUMIF('Results Data'!$B$2:$B$49,$B8,'Results Data'!$E$2:$E$49)+SUMIF('Results Data'!$C$2:$C$49,$B8,'Results Data'!$D$2:$D$49) | I8: =G8-H8 | J8: =D8*3+E8
A9: =ROW()-1 | B9: Aberdeen | C9: =COUNTIF('Results Data'!$B$2:$B$49,$B9)+COUNTIF('Results Data'!$C$2:$C$49,$B9) | D9: =SUMPRODUCT(('Results Data'!$B$2:$B$49=$B9)*('Results Data'!$D$2:$D$49>'Results Data'!$E$2:$E$49))+SUMPRODUCT(('Results Data'!$C$2:$C$49=$B9)*('Results Data'!$E$2:$E$49>'Results Data'!$D$2:$D$49)) | E9: =SUMPRODUCT(('Results Data'!$B$2:$B$49=$B9)*('Results Data'!$D$2:$D$49='Results Data'!$E$2:$E$49))+SUMPRODUCT(('Results Data'!$C$2:$C$49=$B9)*('Results Data'!$E$2:$E$49='Results Data'!$D$2:$D$49)) | F9: =C9-D9-E9 | G9: =SUMIF('Results Data'!$B$2:$B$49,$B9,'Results Data'!$D$2:$D$49)+SUMIF('Results Data'!$C$2:$C$49,$B9,'Results Data'!$E$2:$E$49) | H9: =SUMIF('Results Data'!$B$2:$B$49,$B9,'Results Data'!$E$2:$E$49)+SUMIF('Results Data'!$C$2:$C$49,$B9,'Results Data'!$D$2:$D$49) | I9: =G9-H9 | J9: =D9*3+E9
A10: =ROW()-1 | B10: Motherwell | C10: =COUNTIF('Results Data'!$B$2:$B$49,$B10)+COUNTIF('Results Data'!$C$2:$C$49,$B10) | D10: =SUMPRODUCT(('Results Data'!$B$2:$B$49=$B10)*('Results Data'!$D$2:$D$49>'Results Data'!$E$2:$E$49))+SUMPRODUCT(('Results Data'!$C$2:$C$49=$B10)*('Results Data'!$E$2:$E$49>'Results Data'!$D$2:$D$49)) | E10: =SUMPRODUCT(('Results Data'!$B$2:$B$49=$B10)*('Results Data'!$D$2:$D$49='Results Data'!$E$2:$E$49))+SUMPRODUCT(('Results Data'!$C$2:$C$49=$B10)*('Results Data'!$E$2:$E$49='Results Data'!$D$2:$D$49)) | F10: =C10-D10-E10 | G10: =SUMIF('Results Data'!$B$2:$B$49,$B10,'Results Data'!$D$2:$D$49)+SUMIF('Results Data'!$C$2:$C$49,$B10,'Results Data'!$E$2:$E$49) | H10: =SUMIF('Results Data'!$B$2:$B$49,$B10,'Results Data'!$E$2:$E$49)+SUMIF('Results Data'!$C$2:$C$49,$B10,'Results Data'!$D$2:$D$49) | I10: =G10-H10 | J10: =D10*3+E10
A11: =ROW()-1 | B11: Hibernian | C11: =COUNTIF('Results Data'!$B$2:$B$49,$B11)+COUNTIF('Results Data'!$C$2:$C$49,$B11) | D11: =SUMPRODUCT(('Results Data'!$B$2:$B$49=$B11)*('Results Data'!$D$2:$D$49>'Results Data'!$E$2:$E$49))+SUMPRODUCT(('Results Data'!$C$2:$C$49=$B11)*('Results Data'!$E$2:$E$49>'Results Data'!$D$2:$D$49)) | E11: =SUMPRODUCT(('Results Data'!$B$2:$B$49=$B11)*('Results Data'!$D$2:$D$49='Results Data'!$E$2:$E$49))+SUMPRODUCT(('Results Data'!$C$2:$C$49=$B11)*('Results Data'!$E$2:$E$49='Results Data'!$D$2:$D$49)) | F11: =C11-D11-E11 | G11: =SUMIF('Results Data'!$B$2:$B$49,$B11,'Results Data'!$D$2:$D$49)+SUMIF('Results Data'!$C$2:$C$49,$B11,'Results Data'!$E$2:$E$49) | H11: =SUMIF('Results Data'!$B$2:$B$49,$B11,'Results Data'!$E$2:$E$49)+SUMIF('Results Data'!$C$2:$C$49,$B11,'Results Data'!$D$2:$D$49) | I11: =G11-H11 | J11: =D11*3+E11
A12: =ROW()-1 | B12: Falkirk | C12: =COUNTIF('Results Data'!$B$2:$B$49,$B12)+COUNTIF('Results Data'!$C$2:$C$49,$B12) | D12: =SUMPRODUCT(('Results Data'!$B$2:$B$49=$B12)*('Results Data'!$D$2:$D$49>'Results Data'!$E$2:$E$49))+SUMPRODUCT(('Results Data'!$C$2:$C$49=$B12)*('Results Data'!$E$2:$E$49>'Results Data'!$D$2:$D$49)) | E12: =SUMPRODUCT(('Results Data'!$B$2:$B$49=$B12)*('Results Data'!$D$2:$D$49='Results Data'!$E$2:$E$49))+SUMPRODUCT(('Results Data'!$C$2:$C$49=$B12)*('Results Data'!$E$2:$E$49='Results Data'!$D$2:$D$49)) | F12: =C12-D12-E12 | G12: =SUMIF('Results Data'!$B$2:$B$49,$B12,'Results Data'!$D$2:$D$49)+SUMIF('Results Data'!$C$2:$C$49,$B12,'Results Data'!$E$2:$E$49) | H12: =SUMIF('Results Data'!$B$2:$B$49,$B12,'Results Data'!$E$2:$E$49)+SUMIF('Results Data'!$C$2:$C$49,$B12,'Results Data'!$D$2:$D$49) | I12: =G12-H12 | J12: =D12*3+E12
A13: =ROW()-1 | B13: Kilmarnock | C13: =COUNTIF('Results Data'!$B$2:$B$49,$B13)+COUNTIF('Results Data'!$C$2:$C$49,$B13) | D13: =SUMPRODUCT(('Results Data'!$B$2:$B$49=$B13)*('Results Data'!$D$2:$D$49>'Results Data'!$E$2:$E$49))+SUMPRODUCT(('Results Data'!$C$2:$C$49=$B13)*('Results Data'!$E$2:$E$49>'Results Data'!$D$2:$D$49)) | E13: =SUMPRODUCT(('Results Data'!$B$2:$B$49=$B13)*('Results Data'!$D$2:$D$49='Results Data'!$E$2:$E$49))+SUMPRODUCT(('Results Data'!$C$2:$C$49=$B13)*('Results Data'!$E$2:$E$49='Results Data'!$D$2:$D$49)) | F13: =C13-D13-E13 | G13: =SUMIF('Results Data'!$B$2:$B$49,$B13,'Results Data'!$D$2:$D$49)+SUMIF('Results Data'!$C$2:$C$49,$B13,'Results Data'!$E$2:$E$49) | H13: =SUMIF('Results Data'!$B$2:$B$49,$B13,'Results Data'!$E$2:$E$49)+SUMIF('Results Data'!$C$2:$C$49,$B13,'Results Data'!$D$2:$D$49) | I13: =G13-H13 | J13: =D13*3+E13

Sheet League Summary
A1: Team | B1: League Position | C1: Games Played | D1: Goals For Supremacy Rank | E1: Goals Conceded Supremacy Rank | F1: Goals Above Expected (Total) Rank | G1: xPts Delta Rank | H1: Market Points Rank | I1: Games +ve xG Supremacy | J1: Games -ve xG Supremacy | K1: Avg xG Delta (For) | L1: Avg xG Delta (Against) | M1: Avg Total xG Delta | N1: xPts Delta (Total) | O1: Market xPts (Total)
A2: Celtic | B2: =IFERROR(INDEX('League Table'!$A$2:$A$13,MATCH($A2,'League Table'!$B$2:$B$13,0)),"") | C2: =IFERROR(INDEX('League Table'!$C$2:$C$13,MATCH($A2,'League Table'!$B$2:$B$13,0)),"") | D2: =RANK(K2,K$2:K$13,0) | E2: =RANK(L2,L$2:L$13,1) | F2: =RANK(M2,M$2:M$13,0) | G2: =RANK(N2,N$2:N$13,0) | H2: =RANK(O2,O$2:O$13,0) | I2: =COUNTIF('Celtic'!$R$2:$R$9,">0") | J2: =COUNTIF('Celtic'!$R$2:$R$9,"<0") | K2: =ROUND('Celtic'!$E$15,4) | L2: =ROUND('Celtic'!$E$17,4) | M2: =ROUND('Celtic'!$E$25,4) | N2: =ROUND('Celtic'!$E$31-'Celtic'!$E$32,4) | O2: =ROUND('Celtic'!$E$32,4)
A3: Rangers | B3: =IFERROR(INDEX('League Table'!$A$2:$A$13,MATCH($A3,'League Table'!$B$2:$B$13,0)),"") | C3: =IFERROR(INDEX('League Table'!$C$2:$C$13,MATCH($A3,'League Table'!$B$2:$B$13,0)),"") | D3: =RANK(K3,K$2:K$13,0) | E3: =RANK(L3,L$2:L$13,1) | F3: =RANK(M3,M$2:M$13,0) | G3: =RANK(N3,N$2:N$13,0) | H3: =RANK(O3,O$2:O$13,0) | I3: =COUNTIF('Rangers'!$R$2:$R$9,">0") | J3: =COUNTIF('Rangers'!$R$2:$R$9,"<0") | K3: =ROUND('Rangers'!$E$15,4) | L3: =ROUND('Rangers'!$E$17,4) | M3: =ROUND('Rangers'!$E$25,4) | N3: =ROUND('Rangers'!$E$31-'Rangers'!$E$32,4) | O3: =ROUND('Rangers'!$E$32,4)
A4: Heart of Midlothian | B4: =IFERROR(INDEX('League Table'!$A$2:$A$13,MATCH($A4,'League Table'!$B$2:$B$13,0)),"") | C4: =IFERROR(INDEX('League Table'!$C$2:$C$13,MATCH($A4,'League Table'!$B$2:$B$13,0)),"") | D4: =RANK(K4,K$2:K$13,0) | E4: =RANK(L4,L$2:L$13,1) | F4: =RANK(M4,M$2:M$13,0) | G4: =RANK(N4,N$2:N$13,0) | H4: =RANK(O4,O$2:O$13,0) | I4: =COUNTIF('Heart of Midlothian'!$R$2:$R$9,">0") | J4: =COUNTIF('Heart of Midlothian'!$R$2:$R$9,"<0") | K4: =ROUND('Heart of Midlothian'!$E$15,4) | L4: =ROUND('Heart of Midlothian'!$E$17,4) | M4: =ROUND('Heart of Midlothian'!$E$25,4) | N4: =ROUND('Heart of Midlothian'!$E$31-'Heart of Midlothian'!$E$32,4) | O4: =ROUND('Heart of Midlothian'!$E$32,4)
A5: Dundee | B5: =IFERROR(INDEX('League Table'!$A$2:$A$13,MATCH($A5,'League Table'!$B$2:$B$13,0)),"") | C5: =IFERROR(INDEX('League Table'!$C$2:$C$13,MATCH($A5,'League Table'!$B$2:$B$13,0)),"") | D5: =RANK(K5,K$2:K$13,0) | E5: =RANK(L5,L$2:L$13,1) | F5: =RANK(M5,M$2:M$13,0) | G5: =RANK(N5,N$2:N$13,0) | H5: =RANK(O5,O$2:O$13,0) | I5: =COUNTIF('Dundee'!$R$2:$R$9,">0") | J5: =COUNTIF('Dundee'!$R$2:$R$9,"<0") | K5: =ROUND('Dundee'!$E$15,4) | L5: =ROUND('Dundee'!$E$17,4) | M5: =ROUND('Dundee'!$E$25,4) | N5: =ROUND('Dundee'!$E$31-'Dundee'!$E$32,4) | O5: =ROUND('Dundee'!$E$32,4)
A6: St Johnstone | B6: =IFERROR(INDEX('League Table'!$A$2:$A$13,MATCH($A6,'League Table'!$B$2:$B$13,0)),"") | C6: =IFERROR(INDEX('League Table'!$C$2:$C$13,MATCH($A6,'League Table'!$B$2:$B$13,0)),"") | D6: =RANK(K6,K$2:K$13,0) | E6: =RANK(L6,L$2:L$13,1) | F6: =RANK(M6,M$2:M$13,0) | G6: =RANK(N6,N$2:N$13,0) | H6: =RANK(O6,O$2:O$13,0) | I6: =COUNTIF('St Johnstone'!$R$2:$R$9,">0") | J6: =COUNTIF('St Johnstone'!$R$2:$R$9,"<0") | K6: =ROUND('St Johnstone'!$E$15,4) | L6: =ROUND('St Johnstone'!$E$17,4) | M6: =ROUND('St Johnstone'!$E$25,4) | N6: =ROUND('St Johnstone'!$E$31-'St Johnstone'!$E$32,4) | O6: =ROUND('St Johnstone'!$E$32,4)
A7: Dundee United | B7: =IFERROR(INDEX('League Table'!$A$2:$A$13,MATCH($A7,'League Table'!$B$2:$B$13,0)),"") | C7: =IFERROR(INDEX('League Table'!$C$2:$C$13,MATCH($A7,'League Table'!$B$2:$B$13,0)),"") | D7: =RANK(K7,K$2:K$13,0) | E7: =RANK(L7,L$2:L$13,1) | F7: =RANK(M7,M$2:M$13,0) | G7: =RANK(N7,N$2:N$13,0) | H7: =RANK(O7,O$2:O$13,0) | I7: =COUNTIF('Dundee United'!$R$2:$R$9,">0") | J7: =COUNTIF('Dundee United'!$R$2:$R$9,"<0") | K7: =ROUND('Dundee United'!$E$15,4) | L7: =ROUND('Dundee United'!$E$17,4) | M7: =ROUND('Dundee United'!$E$25,4) | N7: =ROUND('Dundee United'!$E$31-'Dundee United'!$E$32,4) | O7: =ROUND('Dundee United'!$E$32,4)
A8: St Mirren | B8: =IFERROR(INDEX('League Table'!$A$2:$A$13,MATCH($A8,'League Table'!$B$2:$B$13,0)),"") | C8: =IFERROR(INDEX('League Table'!$C$2:$C$13,MATCH($A8,'League Table'!$B$2:$B$13,0)),"") | D8: =RANK(K8,K$2:K$13,0) | E8: =RANK(L8,L$2:L$13,1) | F8: =RANK(M8,M$2:M$13,0) | G8: =RANK(N8,N$2:N$13,0) | H8: =RANK(O8,O$2:O$13,0) | I8: =COUNTIF('St Mirren'!$R$2:$R$9,">0") | J8: =COUNTIF('St Mirren'!$R$2:$R$9,"<0") | K8: =ROUND('St Mirren'!$E$15,4) | L8: =ROUND('St Mirren'!$E$17,4) | M8: =ROUND('St Mirren'!$E$25,4) | N8: =ROUND('St Mirren'!$E$31-'St Mirren'!$E$32,4) | O8: =ROUND('St Mirren'!$E$32,4)
A9: Aberdeen | B9: =IFERROR(INDEX('League Table'!$A$2:$A$13,MATCH($A9,'League Table'!$B$2:$B$13,0)),"") | C9: =IFERROR(INDEX('League Table'!$C$2:$C$13,MATCH($A9,'League Table'!$B$2:$B$13,0)),"") | D9: =RANK(K9,K$2:K$13,0) | E9: =RANK(L9,L$2:L$13,1) | F9: =RANK(M9,M$2:M$13,0) | G9: =RANK(N9,N$2:N$13,0) | H9: =RANK(O9,O$2:O$13,0) | I9: =COUNTIF('Aberdeen'!$R$2:$R$9,">0") | J9: =COUNTIF('Aberdeen'!$R$2:$R$9,"<0") | K9: =ROUND('Aberdeen'!$E$15,4) | L9: =ROUND('Aberdeen'!$E$17,4) | M9: =ROUND('Aberdeen'!$E$25,4) | N9: =ROUND('Aberdeen'!$E$31-'Aberdeen'!$E$32,4) | O9: =ROUND('Aberdeen'!$E$32,4)
A10: Motherwell | B10: =IFERROR(INDEX('League Table'!$A$2:$A$13,MATCH($A10,'League Table'!$B$2:$B$13,0)),"") | C10: =IFERROR(INDEX('League Table'!$C$2:$C$13,MATCH($A10,'League Table'!$B$2:$B$13,0)),"") | D10: =RANK(K10,K$2:K$13,0) | E10: =RANK(L10,L$2:L$13,1) | F10: =RANK(M10,M$2:M$13,0) | G10: =RANK(N10,N$2:N$13,0) | H10: =RANK(O10,O$2:O$13,0) | I10: =COUNTIF('Motherwell'!$R$2:$R$9,">0") | J10: =COUNTIF('Motherwell'!$R$2:$R$9,"<0") | K10: =ROUND('Motherwell'!$E$15,4) | L10: =ROUND('Motherwell'!$E$17,4) | M10: =ROUND('Motherwell'!$E$25,4) | N10: =ROUND('Motherwell'!$E$31-'Motherwell'!$E$32,4) | O10: =ROUND('Motherwell'!$E$32,4)
A11: Hibernian | B11: =IFERROR(INDEX('League Table'!$A$2:$A$13,MATCH($A11,'League Table'!$B$2:$B$13,0)),"") | C11: =IFERROR(INDEX('League Table'!$C$2:$C$13,MATCH($A11,'League Table'!$B$2:$B$13,0)),"") | D11: =RANK(K11,K$2:K$13,0) | E11: =RANK(L11,L$2:L$13,1) | F11: =RANK(M11,M$2:M$13,0) | G11: =RANK(N11,N$2:N$13,0) | H11: =RANK(O11,O$2:O$13,0) | I11: =COUNTIF('Hibernian'!$R$2:$R$9,">0") | J11: =COUNTIF('Hibernian'!$R$2:$R$9,"<0") | K11: =ROUND('Hibernian'!$E$15,4) | L11: =ROUND('Hibernian'!$E$17,4) | M11: =ROUND('Hibernian'!$E$25,4) | N11: =ROUND('Hibernian'!$E$31-'Hibernian'!$E$32,4) | O11: =ROUND('Hibernian'!$E$32,4)
A12: Falkirk | B12: =IFERROR(INDEX('League Table'!$A$2:$A$13,MATCH($A12,'League Table'!$B$2:$B$13,0)),"") | C12: =IFERROR(INDEX('League Table'!$C$2:$C$13,MATCH($A12,'League Table'!$B$2:$B$13,0)),"") | D12: =RANK(K12,K$2:K$13,0) | E12: =RANK(L12,L$2:L$13,1) | F12: =RANK(M12,M$2:M$13,0) | G12: =RANK(N12,N$2:N$13,0) | H12: =RANK(O12,O$2:O$13,0) | I12: =COUNTIF('Falkirk'!$R$2:$R$9,">0") | J12: =COUNTIF('Falkirk'!$R$2:$R$9,"<0") | K12: =ROUND('Falkirk'!$E$15,4) | L12: =ROUND('Falkirk'!$E$17,4) | M12: =ROUND('Falkirk'!$E$25,4) | N12: =ROUND('Falkirk'!$E$31-'Falkirk'!$E$32,4) | O12: =ROUND('Falkirk'!$E$32,4)
A13: Kilmarnock | B13: =IFERROR(INDEX('League Table'!$A$2:$A$13,MATCH($A13,'League Table'!$B$2:$B$13,0)),"") | C13: =IFERROR(INDEX('League Table'!$C$2:$C$13,MATCH($A13,'League Table'!$B$2:$B$13,0)),"") | D13: =RANK(K13,K$2:K$13,0) | E13: =RANK(L13,L$2:L$13,1) | F13: =RANK(M13,M$2:M$13,0) | G13: =RANK(N13,N$2:N$13,0) | H13: =RANK(O13,O$2:O$13,0) | I13: =COUNTIF('Kilmarnock'!$R$2:$R$9,">0") | J13: =COUNTIF('Kilmarnock'!$R$2:$R$9,"<0") | K13: =ROUND('Kilmarnock'!$E$15,4) | L13: =ROUND('Kilmarnock'!$E$17,4) | M13: =ROUND('Kilmarnock'!$E$25,4) | N13: =ROUND('Kilmarnock'!$E$31-'Kilmarnock'!$E$32,4) | O13: =ROUND('Kilmarnock'!$E$32,4)
A15: How to read this sheet
A16: Ranks: 1 = best. Rows are in league-table order (position and games played come from the League Table sheet).
A17: Goals For Supremacy Rank: avg xG Delta (For) - actual xG for minus the pre-match market xG for. Highest = rank 1.
A18: Goals Conceded Supremacy Rank: avg xG Delta (Against) - actual xG against minus pre-match market xG against. The more negative (conceding less than expected), the better the rank, so the most negative = rank 1.
A19: Goals Above Expected (Total) Rank: avg Match Total xG Delta - combined actual xG in the team's games minus the combined pre-match market xG. Highest = rank 1 (games producing the most goals above expectation).
A20: xPts Delta Rank: season-total actual xPts minus market xPts. Highest = rank 1. Market Points Rank: season-total market xPts, highest = rank 1.
A21: Games +ve / -ve xG Supremacy: games where the team's Supremacy Delta (actual xG supremacy minus pre-match expected supremacy) was above / below zero.
A22: Columns K:O hold the underlying numbers the ranks are calculated from.

Sheet Overview
A1: Team | B1: Matches Played | C1: Avg xG Delta (For) | D1: Avg xG Delta (Against) | E1: Avg xG Delta (For, Adj) | F1: Avg xG Delta (Against, Adj) | G1: Avg Supremacy Delta | H1: Current Form (6, For) | I1: Current Form (6, Against) | J1: Total xPts (Actual) | K1: Total xPts (Market) | L1: Avg xPts Delta
A2: Celtic | B2: ='Celtic'!$E$12 | C2: ='Celtic'!$E$15 | D2: ='Celtic'!$E$17 | E2: ='Celtic'!$E$19 | F2: ='Celtic'!$E$21 | G2: ='Celtic'!$E$23 | H2: ='Celtic'!$E$27 | I2: ='Celtic'!$E$28 | J2: ='Celtic'!$E$31 | K2: ='Celtic'!$E$32 | L2: ='Celtic'!$E$33
A3: Dundee United | B3: ='Dundee United'!$E$12 | C3: ='Dundee United'!$E$15 | D3: ='Dundee United'!$E$17 | E3: ='Dundee United'!$E$19 | F3: ='Dundee United'!$E$21 | G3: ='Dundee United'!$E$23 | H3: ='Dundee United'!$E$27 | I3: ='Dundee United'!$E$28 | J3: ='Dundee United'!$E$31 | K3: ='Dundee United'!$E$32 | L3: ='Dundee United'!$E$33
A4: St Mirren | B4: ='St Mirren'!$E$12 | C4: ='St Mirren'!$E$15 | D4: ='St Mirren'!$E$17 | E4: ='St Mirren'!$E$19 | F4: ='St Mirren'!$E$21 | G4: ='St Mirren'!$E$23 | H4: ='St Mirren'!$E$27 | I4: ='St Mirren'!$E$28 | J4: ='St Mirren'!$E$31 | K4: ='St Mirren'!$E$32 | L4: ='St Mirren'!$E$33
A5: Heart of Midlothian | B5: ='Heart of Midlothian'!$E$12 | C5: ='Heart of Midlothian'!$E$15 | D5: ='Heart of Midlothian'!$E$17 | E5: ='Heart of Midlothian'!$E$19 | F5: ='Heart of Midlothian'!$E$21 | G5: ='Heart of Midlothian'!$E$23 | H5: ='Heart of Midlothian'!$E$27 | I5: ='Heart of Midlothian'!$E$28 | J5: ='Heart of Midlothian'!$E$31 | K5: ='Heart of Midlothian'!$E$32 | L5: ='Heart of Midlothian'!$E$33
A6: Dundee | B6: ='Dundee'!$E$12 | C6: ='Dundee'!$E$15 | D6: ='Dundee'!$E$17 | E6: ='Dundee'!$E$19 | F6: ='Dundee'!$E$21 | G6: ='Dundee'!$E$23 | H6: ='Dundee'!$E$27 | I6: ='Dundee'!$E$28 | J6: ='Dundee'!$E$31 | K6: ='Dundee'!$E$32 | L6: ='Dundee'!$E$33
A7: Motherwell | B7: ='Motherwell'!$E$12 | C7: ='Motherwell'!$E$15 | D7: ='Motherwell'!$E$17 | E7: ='Motherwell'!$E$19 | F7: ='Motherwell'!$E$21 | G7: ='Motherwell'!$E$23 | H7: ='Motherwell'!$E$27 | I7: ='Motherwell'!$E$28 | J7: ='Motherwell'!$E$31 | K7: ='Motherwell'!$E$32 | L7: ='Motherwell'!$E$33
A8: Rangers | B8: ='Rangers'!$E$12 | C8: ='Rangers'!$E$15 | D8: ='Rangers'!$E$17 | E8: ='Rangers'!$E$19 | F8: ='Rangers'!$E$21 | G8: ='Rangers'!$E$23 | H8: ='Rangers'!$E$27 | I8: ='Rangers'!$E$28 | J8: ='Rangers'!$E$31 | K8: ='Rangers'!$E$32 | L8: ='Rangers'!$E$33
A9: St Johnstone | B9: ='St Johnstone'!$E$12 | C9: ='St Johnstone'!$E$15 | D9: ='St Johnstone'!$E$17 | E9: ='St Johnstone'!$E$19 | F9: ='St Johnstone'!$E$21 | G9: ='St Johnstone'!$E$23 | H9: ='St Johnstone'!$E$27 | I9: ='St Johnstone'!$E$28 | J9: ='St Johnstone'!$E$31 | K9: ='St Johnstone'!$E$32 | L9: ='St Johnstone'!$E$33
A10: Hibernian | B10: ='Hibernian'!$E$12 | C10: ='Hibernian'!$E$15 | D10: ='Hibernian'!$E$17 | E10: ='Hibernian'!$E$19 | F10: ='Hibernian'!$E$21 | G10: ='Hibernian'!$E$23 | H10: ='Hibernian'!$E$27 | I10: ='Hibernian'!$E$28 | J10: ='Hibernian'!$E$31 | K10: ='Hibernian'!$E$32 | L10: ='Hibernian'!$E$33
A11: Falkirk | B11: ='Falkirk'!$E$12 | C11: ='Falkirk'!$E$15 | D11: ='Falkirk'!$E$17 | E11: ='Falkirk'!$E$19 | F11: ='Falkirk'!$E$21 | G11: ='Falkirk'!$E$23 | H11: ='Falkirk'!$E$27 | I11: ='Falkirk'!$E$28 | J11: ='Falkirk'!$E$31 | K11: ='Falkirk'!$E$32 | L11: ='Falkirk'!$E$33
A12: Kilmarnock | B12: ='Kilmarnock'!$E$12 | C12: ='Kilmarnock'!$E$15 | D12: ='Kilmarnock'!$E$17 | E12: ='Kilmarnock'!$E$19 | F12: ='Kilmarnock'!$E$21 | G12: ='Kilmarnock'!$E$23 | H12: ='Kilmarnock'!$E$27 | I12: ='Kilmarnock'!$E$28 | J12: ='Kilmarnock'!$E$31 | K12: ='Kilmarnock'!$E$32 | L12: ='Kilmarnock'!$E$33
A13: Aberdeen | B13: ='Aberdeen'!$E$12 | C13: ='Aberdeen'!$E$15 | D13: ='Aberdeen'!$E$17 | E13: ='Aberdeen'!$E$19 | F13: ='Aberdeen'!$E$21 | G13: ='Aberdeen'!$E$23 | H13: ='Aberdeen'!$E$27 | I13: ='Aberdeen'!$E$28 | J13: ='Aberdeen'!$E$31 | K13: ='Aberdeen'!$E$32 | L13: ='Aberdeen'!$E$33

Sheet xPts Table
A1: Pos | B1: Team | C1: Matches | D1: xPts (Actual) | E1: xPts (Market) | F1: xPts Delta (Total)
A2: 1 | B2: Dundee United | C2: ='Dundee United'!$E$12 | D2: ='Dundee United'!$E$31 | E2: ='Dundee United'!$E$32 | F2: =D2-E2
A3: 2 | B3: Dundee | C3: ='Dundee'!$E$12 | D3: ='Dundee'!$E$31 | E3: ='Dundee'!$E$32 | F3: =D3-E3
A4: 3 | B4: St Mirren | C4: ='St Mirren'!$E$12 | D4: ='St Mirren'!$E$31 | E4: ='St Mirren'!$E$32 | F4: =D4-E4
A5: 4 | B5: Heart of Midlothian | C5: ='Heart of Midlothian'!$E$12 | D5: ='Heart of Midlothian'!$E$31 | E5: ='Heart of Midlothian'!$E$32 | F5: =D5-E5
A6: 5 | B6: Celtic | C6: ='Celtic'!$E$12 | D6: ='Celtic'!$E$31 | E6: ='Celtic'!$E$32 | F6: =D6-E6
A7: 6 | B7: Rangers | C7: ='Rangers'!$E$12 | D7: ='Rangers'!$E$31 | E7: ='Rangers'!$E$32 | F7: =D7-E7
A8: 7 | B8: St Johnstone | C8: ='St Johnstone'!$E$12 | D8: ='St Johnstone'!$E$31 | E8: ='St Johnstone'!$E$32 | F8: =D8-E8
A9: 8 | B9: Motherwell | C9: ='Motherwell'!$E$12 | D9: ='Motherwell'!$E$31 | E9: ='Motherwell'!$E$32 | F9: =D9-E9
A10: 9 | B10: Kilmarnock | C10: ='Kilmarnock'!$E$12 | D10: ='Kilmarnock'!$E$31 | E10: ='Kilmarnock'!$E$32 | F10: =D10-E10
A11: 10 | B11: Falkirk | C11: ='Falkirk'!$E$12 | D11: ='Falkirk'!$E$31 | E11: ='Falkirk'!$E$32 | F11: =D11-E11
A12: 11 | B12: Aberdeen | C12: ='Aberdeen'!$E$12 | D12: ='Aberdeen'!$E$31 | E12: ='Aberdeen'!$E$32 | F12: =D12-E12
A13: 12 | B13: Hibernian | C13: ='Hibernian'!$E$12 | D13: ='Hibernian'!$E$31 | E13: ='Hibernian'!$E$32 | F13: =D13-E13

Sheet Dashboard
A1: League Dashboard
A2: Charts reference Overview / xPts Table live - re-run the pipeline and they update automatically.

Sheet Data Quality
A1: Data Quality Checker
A3: No issues found across 48 fixtures.

Sheet Match Log
A1: Date | B1: Home Team | C1: Away Team | D1: Home Goals | E1: Away Goals | F1: Home xG Pre-Match | G1: Away xG Pre-Match | H1: Home xG Actual | I1: Away xG Actual | J1: Home xG Delta | K1: Away xG Delta | L1: Supremacy Delta (Home) | M1: Total xG Delta | N1: Home xPts (Actual) | O1: Away xPts (Actual) | P1: Home xPts (Market) | Q1: Away xPts (Market)
A2: 2026-07-31 | B2: Dundee United | C2: Rangers | D2: 1 | E2: 1 | F2: 1.05 | G2: 2.21 | H2: 1.64 | I2: 1.46 | J2: 0.59 | K2: -0.75 | L2: 1.34 | M2: -0.16 | N2: 1.5 | O2: 1.26 | P2: 0.7 | Q2: 2.11
A3: 2026-08-01 | B3: Aberdeen | C3: Heart of Midlothian | D3: 2 | E3: 1 | F3: 1.27 | G3: 1.59 | H3: 2.66 | I3: 1.83 | J3: 1.39 | K3: 0.24 | L3: 1.15 | M3: 1.63 | N3: 1.85 | O3: 0.96 | P3: 1.17 | Q3: 1.59
A4: 2026-08-01 | B4: Falkirk | C4: St Mirren | D4: 0 | E4: 2 | F4: 1.64 | G4: 1.17 | H4: 0.55 | I4: 1.57 | J4: -1.09 | K4: 0.4 | L4: -1.49 | M4: -0.69 | N4: 0.63 | O4: 2.12 | P4: 1.7 | Q4: 1.06
A5: 2026-08-02 | B5: St Johnstone | C5: Kilmarnock | D5: 4 | E5: 3 | F5: 1.55 | G5: 1.24 | H5: 2.03 | I5: 0.92 | J5: 0.48 | K5: -0.32 | L5: 0.8 | M5: 0.16 | N5: 2.1 | O5: 0.69 | P5: 1.59 | Q5: 1.16
A6: 2026-08-02 | B6: Hibernian | C6: Motherwell | D6: 1 | E6: 2 | F6: 1.52 | G6: 1.25 | H6: 1.94 | I6: 2.19 | J6: 0.42 | K6: 0.94 | L6: -0.52 | M6: 1.37 | N6: 1.26 | O6: 1.54 | P6: 1.56 | Q6: 1.19
A7: 2026-08-03 | B7: Celtic | C7: Dundee | D7: 1 | E7: 0 | F7: 2.83 | G7: 0.81 | H7: 2.25 | I7: 0.49 | J7: -0.58 | K7: -0.32 | L7: -0.26 | M7: -0.9 | N7: 2.49 | O7: 0.35 | P7: 2.5 | Q7: 0.37
A8: 2026-08-08 | B8: St Mirren | C8: St Johnstone | D8: 1 | E8: 0 | F8: 1.48 | G8: 1.23 | H8: 1.58 | I8: 1.17 | J8: 0.1 | K8: -0.06 | L8: 0.16 | M8: 0.05 | N8: 1.66 | O8: 1.1 | P8: 1.54 | Q8: 1.2
A9: 2026-08-08 | B9: Dundee | C9: Aberdeen | D9: 2 | E9: 0 | F9: 1.34 | G9: 1.41 | H9: 1.83 | I9: 0.71 | J9: 0.49 | K9: -0.7 | L9: 1.18 | M9: -0.21 | N9: 2.14 | O9: 0.64 | P9: 1.33 | Q9: 1.42
A10: 2026-08-09 | B10: Motherwell | C10: Falkirk | D10: 0 | E10: 0 | F10: 1.78 | G10: 1.1 | H10: 1.27 | I10: 0.55 | J10: -0.51 | K10: -0.55 | L10: 0.05 | M10: -1.06 | N10: 1.92 | O10: 0.78 | P10: 1.83 | Q10: 0.94
A11: 2026-08-09 | B11: Kilmarnock | C11: Celtic | D11: 1 | E11: 5 | F11: 0.98 | G11: 2.4 | H11: 0.98 | I11: 5.44 | J11: 0 | K11: 3.04 | L11: -3.04 | M11: 3.04 | N11: 0.08 | O11: 2.82 | P11: 0.59 | Q11: 2.24
A12: 2026-08-09 | B12: Heart of Midlothian | C12: Dundee United | D12: 4 | E12: 0 | F12: 1.92 | G12: 0.98 | H12: 2.15 | I12: 0.58 | J12: 0.23 | K12: -0.4 | L12: 0.62 | M12: -0.17 | N12: 2.39 | O12: 0.43 | P12: 2 | Q12: 0.78
A13: 2026-08-09 | B13: Rangers | C13: Hibernian | D13: 1 | E13: 2 | F13: 2.13 | G13: 1.02 | H13: 2.22 | I13: 1.7 | J13: 0.09 | K13: 0.68 | L13: -0.59 | M13: 0.77 | N13: 1.7 | O13: 1.1 | P13: 2.08 | Q13: 0.72
... A49: 2026-10-11 | B49: Motherwell | C49: Celtic | D49: 0 | E49: 2 | F49: 1.16 | G49: 2.19 | H49: 1.05 | I49: 2.85 | J49: -0.11 | K49: 0.66 | L49: -0.77 | M49: 0.55 | N49: 0.48 | O49: 2.38 | P49: 0.78 | Q49: 2.02

Sheet Home & Away Splits
A1: Supremacy Delta - Total / Home / Away
A2: Team | B2: Total Avg | C2: Total Median | D2: Home Avg | E2: Home Median | F2: Away Avg | G2: Away Median
A3: Dundee United | B3: 0.45 | C3: 0.81 | D3: 0.68 | E3: 0.97 | F3: 0.22 | G3: 0.08
A4: Celtic | B4: 0.35 | C4: 0.04 | D4: -0.23 | E4: -0.11 | F4: 0.94 | G4: 0.4
A5: Dundee | B5: 0.27 | C5: 0.39 | D5: 0.41 | E5: 0.74 | F5: 0.13 | G5: 0.16
A6: Heart of Midlothian | B6: 0.11 | C6: 0.24 | D6: 0.71 | E6: 0.48 | F6: -0.49 | G6: -0.72
A7: Rangers | B7: 0.08 | C7: -0.42 | D7: -0.07 | E7: -0.49 | F7: 0.22 | G7: 0.29
A8: St Mirren | B8: 0.03 | C8: 0.24 | D8: -0.06 | E8: 0.07 | F8: 0.12 | G8: 0.36
A9: St Johnstone | B9: -0.06 | C9: -0.12 | D9: 0.22 | E9: 0.44 | F9: -0.34 | G9: -0.15
A10: Aberdeen | B10: -0.13 | C10: 0.03 | D10: -0.15 | E10: -0.36 | F10: -0.11 | G10: 0.03
A11: Falkirk | B11: -0.16 | C11: -0.06 | D11: -0.06 | E11: 0.19 | F11: -0.26 | G11: -0.45
A12: Hibernian | B12: -0.3 | C12: -0.31 | D12: -0.54 | E12: -0.31 | F12: -0.07 | G12: -0.11
A13: Motherwell | B13: -0.3 | C13: -0.45 | D13: 0.07 | E13: -0.32 | F13: -0.67 | G13: -0.45
A14: Kilmarnock | B14: -0.34 | C14: -0.47 | D14: -1.59 | E14: -1.5 | F14: 0.93 | G14: 1.21
A16: Total Goals - Total / Home / Away
A17: Team | B17: Total GF | C17: Total GA | D17: Home GF | E17: Home GA | F17: Away GF | G17: Away GA
A18: Dundee United | B18: 10 | C18: 11 | D18: 3 | E18: 4 | F18: 7 | G18: 7
A19: Celtic | B19: 16 | C19: 4 | D19: 6 | E19: 2 | F19: 10 | G19: 2
A20: Dundee | B20: 11 | C20: 8 | D20: 6 | E20: 4 | F20: 5 | G20: 4
A21: Heart of Midlothian | B21: 19 | C21: 8 | D21: 13 | E21: 2 | F21: 6 | G21: 6
A22: Rangers | B22: 11 | C22: 5 | D22: 6 | E22: 3 | F22: 5 | G22: 2
A23: St Mirren | B23: 8 | C23: 14 | D23: 5 | E23: 8 | F23: 3 | G23: 6
A24: St Johnstone | B24: 10 | C24: 10 | D24: 7 | E24: 6 | F24: 3 | G24: 4
A25: Aberdeen | B25: 7 | C25: 9 | D25: 2 | E25: 3 | F25: 5 | G25: 6
A26: Falkirk | B26: 7 | C26: 11 | D26: 4 | E26: 7 | F26: 3 | G26: 4
A27: Hibernian | B27: 8 | C27: 12 | D27: 3 | E27: 7 | F27: 5 | G27: 5
A28: Motherwell | B28: 9 | C28: 13 | D28: 3 | E28: 6 | F28: 6 | G28: 7
A29: Kilmarnock | B29: 7 | C29: 18 | D29: 2 | E29: 11 | F29: 5 | G29: 7

Sheet Supremacy Delta
A1: Team | B1: Average | C1: MW1 | D1: MW2 | E1: MW3 | F1: MW4 | G1: MW5 | H1: MW6 | I1: MW7 | J1: MW8
A2: Dundee United | B2: ='Dundee United'!$E$23 | C2: ='Dundee United'!$R$2 | D2: ='Dundee United'!$R$3 | E2: ='Dundee United'!$R$4 | F2: ='Dundee United'!$R$5 | G2: ='Dundee United'!$R$6 | H2: ='Dundee United'!$R$7 | I2: ='Dundee United'!$R$8 | J2: ='Dundee United'!$R$9
A3: Celtic | B3: ='Celtic'!$E$23 | C3: ='Celtic'!$R$2 | D3: ='Celtic'!$R$3 | E3: ='Celtic'!$R$4 | F3: ='Celtic'!$R$5 | G3: ='Celtic'!$R$6 | H3: ='Celtic'!$R$7 | I3: ='Celtic'!$R$8 | J3: ='Celtic'!$R$9
A4: Dundee | B4: ='Dundee'!$E$23 | C4: ='Dundee'!$R$2 | D4: ='Dundee'!$R$3 | E4: ='Dundee'!$R$4 | F4: ='Dundee'!$R$5 | G4: ='Dundee'!$R$6 | H4: ='Dundee'!$R$7 | I4: ='Dundee'!$R$8 | J4: ='Dundee'!$R$9
A5: Heart of Midlothian | B5: ='Heart of Midlothian'!$E$23 | C5: ='Heart of Midlothian'!$R$2 | D5: ='Heart of Midlothian'!$R$3 | E5: ='Heart of Midlothian'!$R$4 | F5: ='Heart of Midlothian'!$R$5 | G5: ='Heart of Midlothian'!$R$6 | H5: ='Heart of Midlothian'!$R$7 | I5: ='Heart of Midlothian'!$R$8 | J5: ='Heart of Midlothian'!$R$9
A6: Rangers | B6: ='Rangers'!$E$23 | C6: ='Rangers'!$R$2 | D6: ='Rangers'!$R$3 | E6: ='Rangers'!$R$4 | F6: ='Rangers'!$R$5 | G6: ='Rangers'!$R$6 | H6: ='Rangers'!$R$7 | I6: ='Rangers'!$R$8 | J6: ='Rangers'!$R$9
A7: St Mirren | B7: ='St Mirren'!$E$23 | C7: ='St Mirren'!$R$2 | D7: ='St Mirren'!$R$3 | E7: ='St Mirren'!$R$4 | F7: ='St Mirren'!$R$5 | G7: ='St Mirren'!$R$6 | H7: ='St Mirren'!$R$7 | I7: ='St Mirren'!$R$8 | J7: ='St Mirren'!$R$9
A8: St Johnstone | B8: ='St Johnstone'!$E$23 | C8: ='St Johnstone'!$R$2 | D8: ='St Johnstone'!$R$3 | E8: ='St Johnstone'!$R$4 | F8: ='St Johnstone'!$R$5 | G8: ='St Johnstone'!$R$6 | H8: ='St Johnstone'!$R$7 | I8: ='St Johnstone'!$R$8 | J8: ='St Johnstone'!$R$9
A9: Aberdeen | B9: ='Aberdeen'!$E$23 | C9: ='Aberdeen'!$R$2 | D9: ='Aberdeen'!$R$3 | E9: ='Aberdeen'!$R$4 | F9: ='Aberdeen'!$R$5 | G9: ='Aberdeen'!$R$6 | H9: ='Aberdeen'!$R$7 | I9: ='Aberdeen'!$R$8 | J9: ='Aberdeen'!$R$9
A10: Falkirk | B10: ='Falkirk'!$E$23 | C10: ='Falkirk'!$R$2 | D10: ='Falkirk'!$R$3 | E10: ='Falkirk'!$R$4 | F10: ='Falkirk'!$R$5 | G10: ='Falkirk'!$R$6 | H10: ='Falkirk'!$R$7 | I10: ='Falkirk'!$R$8 | J10: ='Falkirk'!$R$9
A11: Hibernian | B11: ='Hibernian'!$E$23 | C11: ='Hibernian'!$R$2 | D11: ='Hibernian'!$R$3 | E11: ='Hibernian'!$R$4 | F11: ='Hibernian'!$R$5 | G11: ='Hibernian'!$R$6 | H11: ='Hibernian'!$R$7 | I11: ='Hibernian'!$R$8 | J11: ='Hibernian'!$R$9
A12: Motherwell | B12: ='Motherwell'!$E$23 | C12: ='Motherwell'!$R$2 | D12: ='Motherwell'!$R$3 | E12: ='Motherwell'!$R$4 | F12: ='Motherwell'!$R$5 | G12: ='Motherwell'!$R$6 | H12: ='Motherwell'!$R$7 | I12: ='Motherwell'!$R$8 | J12: ='Motherwell'!$R$9
A13: Kilmarnock | B13: ='Kilmarnock'!$E$23 | C13: ='Kilmarnock'!$R$2 | D13: ='Kilmarnock'!$R$3 | E13: ='Kilmarnock'!$R$4 | F13: ='Kilmarnock'!$R$5 | G13: ='Kilmarnock'!$R$6 | H13: ='Kilmarnock'!$R$7 | I13: ='Kilmarnock'!$R$8 | J13: ='Kilmarnock'!$R$9

Sheet Supremacy Delta (Home)
A1: Team | B1: Average | C1: H1 | D1: H2 | E1: H3 | F1: H4
A2: Heart of Midlothian | B2: 0.71 | C2: 0.62 | D2: 0.13 | E2: 0.34 | F2: 1.74
A3: Dundee United | B3: 0.68 | C3: 1.34 | D3: -0.55 | E3: 0.85 | F3: 1.09
A4: Dundee | B4: 0.41 | C4: 1.18 | D4: -1.03 | E4: 0.97 | F4: 0.51
A5: St Johnstone | B5: 0.22 | C5: 0.8 | D5: 0.8 | E5: 0.07 | F5: -0.79
A6: Motherwell | B6: 0.06 | C6: 0.05 | D6: 1.68 | E6: -0.7 | F6: -0.77
A7: Falkirk | B7: -0.06 | C7: -1.49 | D7: 0.44 | E7: 0.88 | F7: -0.06
A8: St Mirren | B8: -0.06 | C8: 0.16 | D8: 0.39 | E8: -0.02 | F8: -0.78
A9: Rangers | B9: -0.07 | C9: -0.59 | D9: 2.31 | E9: -0.39 | F9: -1.59
A10: Aberdeen | B10: -0.15 | C10: 1.15 | D10: -1.01 | E10: -0.83 | F10: 0.1
A11: Celtic | B11: -0.23 | C11: -0.26 | D11: 0.93 | E11: 0.05 | F11: -1.65
A12: Hibernian | B12: -0.54 | C12: -0.52 | D12: 0.55 | E12: -2.08 | F12: -0.1
A13: Kilmarnock | B13: -1.59 | C13: -3.04 | D13: -2.4 | E13: -0.33 | F13: -0.61

Sheet Supremacy Delta (Away)
A1: Team | B1: Average | C1: A1 | D1: A2 | E1: A3 | F1: A4
A2: Celtic | B2: 0.94 | C2: 3.04 | D2: 0.02 | E2: -0.07 | F2: 0.77
A3: Kilmarnock | B3: 0.93 | C3: -0.8 | D3: 0.83 | E3: 2.08 | F3: 1.59
A4: Dundee United | B4: 0.22 | C4: -0.62 | D4: 2.4 | E4: -1.68 | F4: 0.78
A5: Rangers | B5: 0.22 | C5: -1.34 | D5: 1.01 | E5: -0.44 | F5: 1.65
A6: Dundee | B6: 0.13 | C6: 0.26 | D6: 0.55 | E6: -0.34 | F6: 0.06
A7: St Mirren | B7: 0.12 | C7: 1.49 | D7: 0.33 | E7: 0.39 | F7: -1.74
A8: Hibernian | B8: -0.07 | C8: 0.59 | D8: 1.03 | E8: -0.8 | F8: -1.09
A9: Aberdeen | B9: -0.11 | C9: -1.18 | D9: -0.05 | E9: 0.7 | F9: 0.1
A10: Falkirk | B10: -0.26 | C10: -0.05 | D10: -0.93 | E10: -0.85 | F10: 0.79
A11: St Johnstone | B11: -0.34 | C11: -0.16 | D11: -0.13 | E11: -0.97 | F11: -0.1
A12: Heart of Midlothian | B12: -0.49 | C12: -1.15 | D12: -0.55 | E12: -0.88 | F12: 0.61
A13: Motherwell | B13: -0.67 | C13: 0.52 | D13: -0.39 | E13: -2.31 | F13: -0.51

Sheet Total xG Delta
A1: Team | B1: Average | C1: MW1 | D1: MW2 | E1: MW3 | F1: MW4 | G1: MW5 | H1: MW6 | I1: MW7 | J1: MW8 | K1: Median
A2: St Mirren | B2: ='St Mirren'!$E$25 | C2: ='St Mirren'!$S$2 | D2: ='St Mirren'!$S$3 | E2: ='St Mirren'!$S$4 | F2: ='St Mirren'!$S$5 | G2: ='St Mirren'!$S$6 | H2: ='St Mirren'!$S$7 | I2: ='St Mirren'!$S$8 | J2: ='St Mirren'!$S$9 | K2: ='St Mirren'!$E$26
A3: Motherwell | B3: ='Motherwell'!$E$25 | C3: ='Motherwell'!$S$2 | D3: ='Motherwell'!$S$3 | E3: ='Motherwell'!$S$4 | F3: ='Motherwell'!$S$5 | G3: ='Motherwell'!$S$6 | H3: ='Motherwell'!$S$7 | I3: ='Motherwell'!$S$8 | J3: ='Motherwell'!$S$9 | K3: ='Motherwell'!$E$26
A4: Celtic | B4: ='Celtic'!$E$25 | C4: ='Celtic'!$S$2 | D4: ='Celtic'!$S$3 | E4: ='Celtic'!$S$4 | F4: ='Celtic'!$S$5 | G4: ='Celtic'!$S$6 | H4: ='Celtic'!$S$7 | I4: ='Celtic'!$S$8 | J4: ='Celtic'!$S$9 | K4: ='Celtic'!$E$26
A5: Hibernian | B5: ='Hibernian'!$E$25 | C5: ='Hibernian'!$S$2 | D5: ='Hibernian'!$S$3 | E5: ='Hibernian'!$S$4 | F5: ='Hibernian'!$S$5 | G5: ='Hibernian'!$S$6 | H5: ='Hibernian'!$S$7 | I5: ='Hibernian'!$S$8 | J5: ='Hibernian'!$S$9 | K5: ='Hibernian'!$E$26
A6: Heart of Midlothian | B6: ='Heart of Midlothian'!$E$25 | C6: ='Heart of Midlothian'!$S$2 | D6: ='Heart of Midlothian'!$S$3 | E6: ='Heart of Midlothian'!$S$4 | F6: ='Heart of Midlothian'!$S$5 | G6: ='Heart of Midlothian'!$S$6 | H6: ='Heart of Midlothian'!$S$7 | I6: ='Heart of Midlothian'!$S$8 | J6: ='Heart of Midlothian'!$S$9 | K6: ='Heart of Midlothian'!$E$26
A7: Kilmarnock | B7: ='Kilmarnock'!$E$25 | C7: ='Kilmarnock'!$S$2 | D7: ='Kilmarnock'!$S$3 | E7: ='Kilmarnock'!$S$4 | F7: ='Kilmarnock'!$S$5 | G7: ='Kilmarnock'!$S$6 | H7: ='Kilmarnock'!$S$7 | I7: ='Kilmarnock'!$S$8 | J7: ='Kilmarnock'!$S$9 | K7: ='Kilmarnock'!$E$26
A8: St Johnstone | B8: ='St Johnstone'!$E$25 | C8: ='St Johnstone'!$S$2 | D8: ='St Johnstone'!$S$3 | E8: ='St Johnstone'!$S$4 | F8: ='St Johnstone'!$S$5 | G8: ='St Johnstone'!$S$6 | H8: ='St Johnstone'!$S$7 | I8: ='St Johnstone'!$S$8 | J8: ='St Johnstone'!$S$9 | K8: ='St Johnstone'!$E$26
A9: Dundee United | B9: ='Dundee United'!$E$25 | C9: ='Dundee United'!$S$2 | D9: ='Dundee United'!$S$3 | E9: ='Dundee United'!$S$4 | F9: ='Dundee United'!$S$5 | G9: ='Dundee United'!$S$6 | H9: ='Dundee United'!$S$7 | I9: ='Dundee United'!$S$8 | J9: ='Dundee United'!$S$9 | K9: ='Dundee United'!$E$26
A10: Falkirk | B10: ='Falkirk'!$E$25 | C10: ='Falkirk'!$S$2 | D10: ='Falkirk'!$S$3 | E10: ='Falkirk'!$S$4 | F10: ='Falkirk'!$S$5 | G10: ='Falkirk'!$S$6 | H10: ='Falkirk'!$S$7 | I10: ='Falkirk'!$S$8 | J10: ='Falkirk'!$S$9 | K10: ='Falkirk'!$E$26
A11: Rangers | B11: ='Rangers'!$E$25 | C11: ='Rangers'!$S$2 | D11: ='Rangers'!$S$3 | E11: ='Rangers'!$S$4 | F11: ='Rangers'!$S$5 | G11: ='Rangers'!$S$6 | H11: ='Rangers'!$S$7 | I11: ='Rangers'!$S$8 | J11: ='Rangers'!$S$9 | K11: ='Rangers'!$E$26
A12: Dundee | B12: ='Dundee'!$E$25 | C12: ='Dundee'!$S$2 | D12: ='Dundee'!$S$3 | E12: ='Dundee'!$S$4 | F12: ='Dundee'!$S$5 | G12: ='Dundee'!$S$6 | H12: ='Dundee'!$S$7 | I12: ='Dundee'!$S$8 | J12: ='Dundee'!$S$9 | K12: ='Dundee'!$E$26
A13: Aberdeen | B13: ='Aberdeen'!$E$25 | C13: ='Aberdeen'!$S$2 | D13: ='Aberdeen'!$S$3 | E13: ='Aberdeen'!$S$4 | F13: ='Aberdeen'!$S$5 | G13: ='Aberdeen'!$S$6 | H13: ='Aberdeen'!$S$7 | I13: ='Aberdeen'!$S$8 | J13: ='Aberdeen'!$S$9 | K13: ='Aberdeen'!$E$26

Sheet xPts Delta
A1: Team | B1: Average | C1: MW1 | D1: MW2 | E1: MW3 | F1: MW4 | G1: MW5 | H1: MW6 | I1: MW7 | J1: MW8
A2: Dundee United | B2: ='Dundee United'!$E$33 | C2: ='Dundee United'!$V$2 | D2: ='Dundee United'!$V$3 | E2: ='Dundee United'!$V$4 | F2: ='Dundee United'!$V$5 | G2: ='Dundee United'!$V$6 | H2: ='Dundee United'!$V$7 | I2: ='Dundee United'!$V$8 | J2: ='Dundee United'!$V$9
A3: Dundee | B3: ='Dundee'!$E$33 | C3: ='Dundee'!$V$2 | D3: ='Dundee'!$V$3 | E3: ='Dundee'!$V$4 | F3: ='Dundee'!$V$5 | G3: ='Dundee'!$V$6 | H3: ='Dundee'!$V$7 | I3: ='Dundee'!$V$8 | J3: ='Dundee'!$V$9
A4: St Mirren | B4: ='St Mirren'!$E$33 | C4: ='St Mirren'!$V$2 | D4: ='St Mirren'!$V$3 | E4: ='St Mirren'!$V$4 | F4: ='St Mirren'!$V$5 | G4: ='St Mirren'!$V$6 | H4: ='St Mirren'!$V$7 | I4: ='St Mirren'!$V$8 | J4: ='St Mirren'!$V$9
A5: Heart of Midlothian | B5: ='Heart of Midlothian'!$E$33 | C5: ='Heart of Midlothian'!$V$2 | D5: ='Heart of Midlothian'!$V$3 | E5: ='Heart of Midlothian'!$V$4 | F5: ='Heart of Midlothian'!$V$5 | G5: ='Heart of Midlothian'!$V$6 | H5: ='Heart of Midlothian'!$V$7 | I5: ='Heart of Midlothian'!$V$8 | J5: ='Heart of Midlothian'!$V$9
A6: Celtic | B6: ='Celtic'!$E$33 | C6: ='Celtic'!$V$2 | D6: ='Celtic'!$V$3 | E6: ='Celtic'!$V$4 | F6: ='Celtic'!$V$5 | G6: ='Celtic'!$V$6 | H6: ='Celtic'!$V$7 | I6: ='Celtic'!$V$8 | J6: ='Celtic'!$V$9
A7: Rangers | B7: ='Rangers'!$E$33 | C7: ='Rangers'!$V$2 | D7: ='Rangers'!$V$3 | E7: ='Rangers'!$V$4 | F7: ='Rangers'!$V$5 | G7: ='Rangers'!$V$6 | H7: ='Rangers'!$V$7 | I7: ='Rangers'!$V$8 | J7: ='Rangers'!$V$9
A8: Motherwell | B8: ='Motherwell'!$E$33 | C8: ='Motherwell'!$V$2 | D8: ='Motherwell'!$V$3 | E8: ='Motherwell'!$V$4 | F8: ='Motherwell'!$V$5 | G8: ='Motherwell'!$V$6 | H8: ='Motherwell'!$V$7 | I8: ='Motherwell'!$V$8 | J8: ='Motherwell'!$V$9
A9: St Johnstone | B9: ='St Johnstone'!$E$33 | C9: ='St Johnstone'!$V$2 | D9: ='St Johnstone'!$V$3 | E9: ='St Johnstone'!$V$4 | F9: ='St Johnstone'!$V$5 | G9: ='St Johnstone'!$V$6 | H9: ='St Johnstone'!$V$7 | I9: ='St Johnstone'!$V$8 | J9: ='St Johnstone'!$V$9
A10: Kilmarnock | B10: ='Kilmarnock'!$E$33 | C10: ='Kilmarnock'!$V$2 | D10: ='Kilmarnock'!$V$3 | E10: ='Kilmarnock'!$V$4 | F10: ='Kilmarnock'!$V$5 | G10: ='Kilmarnock'!$V$6 | H10: ='Kilmarnock'!$V$7 | I10: ='Kilmarnock'!$V$8 | J10: ='Kilmarnock'!$V$9
A11: Falkirk | B11: ='Falkirk'!$E$33 | C11: ='Falkirk'!$V$2 | D11: ='Falkirk'!$V$3 | E11: ='Falkirk'!$V$4 | F11: ='Falkirk'!$V$5 | G11: ='Falkirk'!$V$6 | H11: ='Falkirk'!$V$7 | I11: ='Falkirk'!$V$8 | J11: ='Falkirk'!$V$9
A12: Aberdeen | B12: ='Aberdeen'!$E$33 | C12: ='Aberdeen'!$V$2 | D12: ='Aberdeen'!$V$3 | E12: ='Aberdeen'!$V$4 | F12: ='Aberdeen'!$V$5 | G12: ='Aberdeen'!$V$6 | H12: ='Aberdeen'!$V$7 | I12: ='Aberdeen'!$V$8 | J12: ='Aberdeen'!$V$9
A13: Hibernian | B13: ='Hibernian'!$E$33 | C13: ='Hibernian'!$V$2 | D13: ='Hibernian'!$V$3 | E13: ='Hibernian'!$V$4 | F13: ='Hibernian'!$V$5 | G13: ='Hibernian'!$V$6 | H13: ='Hibernian'!$V$7 | I13: ='Hibernian'!$V$8 | J13: ='Hibernian'!$V$9

Sheet Aberdeen
A1: Date | B1: Opponent | C1: Venue | D1: Goals For | E1: Goals Against | F1: xG Pre-Match (For) | G1: xG Pre-Match (Against) | H1: xG Actual (For) | I1: xG Actual (Against) | J1: xG Delta (For) | K1: xG Delta (Against) | L1: Rolling Delta (For) | M1: Rolling Delta (Against) | N1: xG Delta (For, Adj) | O1: xG Delta (Against, Adj) | P1: Rolling Delta (For, Adj) | Q1: Rolling Delta (Against, Adj) | R1: Supremacy Delta | S1: Match Total xG Delta | T1: xPts (Actual) | U1: xPts (Market) | V1: xPts Delta | W1: xPts (Actual, Cum.) | X1: xPts (Market, Cum.) | Z1: Goals vs expected
A2: 2026-08-01 | B2: Heart of Midlothian | C2: Home | D2: 2 | E2: 1 | F2: 1.27 | G2: 1.59 | H2: 2.66 | I2: 1.83 | J2: 1.39 | K2: 0.24 | L2: 1.39 | M2: 0.24 | N2: 1.46 | O2: 0.03 | P2: 1.46 | Q2: 0.03 | R2: =(H2-I2)-(F2-G2) | S2: =(H2+I2)-(F2+G2) | T2: 1.85 | U2: 1.17 | V2: 0.69 | W2: 1.85 | X2: 1.17 | Z2: Expected = the pre-match market xG (what the odds implied) for each side.
A3: 2026-08-08 | B3: Dundee | C3: Away | D3: 0 | E3: 2 | F3: 1.41 | G3: 1.34 | H3: 0.71 | I3: 1.83 | J3: -0.7 | K3: 0.49 | L3: 0.34 | M3: 0.36 | N3: -0.64 | O3: 0.4 | P3: 0.41 | Q3: 0.21 | R3: =(H3-I3)-(F3-G3) | S3: =(H3+I3)-(F3+G3) | T3: 0.64 | U3: 1.42 | V3: -0.78 | W3: 2.49 | X3: 2.58 | Z3: Games vs expected | AA3: Above | AB3: Below
A4: 2026-08-30 | B4: Rangers | C4: Home | D4: 0 | E4: 1 | F4: 1.14 | G4: 1.88 | H4: 0.35 | I4: 2.1 | J4: -0.79 | K4: 0.23 | L4: -0.03 | M4: 0.32 | N4: -0.88 | O4: 0.19 | P4: -0.02 | Q4: 0.21 | R4: =(H4-I4)-(F4-G4) | S4: =(H4+I4)-(F4+G4) | T4: 0.31 | U4: 0.91 | V4: -0.6 | W4: 2.8 | X4: 3.49 | Z4: xG For vs expected | AA4: =COUNTIF($J$2:$J$9,">0") | AB4: =COUNTIF($J$2:$J$9,"<0")
A5: 2026-09-02 | B5: Celtic | C5: Away | D5: 0 | E5: 3 | F5: 0.8 | G5: 2.74 | H5: 0.68 | I5: 2.67 | J5: -0.12 | K5: -0.07 | L5: -0.05 | M5: 0.22 | N5: -0.14 | O5: -0.49 | P5: -0.05 | Q5: 0.03 | R5: =(H5-I5)-(F5-G5) | S5: =(H5+I5)-(F5+G5) | T5: 0.35 | U5: 0.39 | V5: -0.04 | W5: 3.15 | X5: 3.88 | Z5: xG Against vs expected | AA5: =COUNTIF($K$2:$K$9,">0") | AB5: =COUNTIF($K$2:$K$9,"<0")
A6: 2026-09-05 | B6: Kilmarnock | C6: Home | D6: 0 | E6: 0 | F6: 1.88 | G6: 1.08 | H6: 1.08 | I6: 1.11 | J6: -0.8 | K6: 0.03 | L6: -0.2 | M6: 0.18 | N6: -1.23 | O6: 0.1 | P6: -0.29 | Q6: 0.05 | R6: =(H6-I6)-(F6-G6) | S6: =(H6+I6)-(F6+G6) | T6: 1.33 | U6: 1.9 | V6: -0.57 | W6: 4.48 | X6: 5.78 | Z6: Goals For vs expected | AA6: =SUMPRODUCT(--($D$2:$D$9>$F$2:$F$9)) | AB6: =SUMPRODUCT(--($D$2:$D$9<$F$2:$F$9))
A7: 2026-09-15 | B7: Motherwell | C7: Away | D7: 4 | E7: 0 | F7: 1.13 | G7: 1.78 | H7: 0.9 | I7: 0.85 | J7: -0.23 | K7: -0.93 | L7: -0.21 | M7: 0 | N7: -0.7 | O7: -1.15 | P7: -0.35 | Q7: -0.15 | R7: =(H7-I7)-(F7-G7) | S7: =(H7+I7)-(F7+G7) | T7: 1.37 | U7: 0.96 | V7: 0.42 | W7: 5.86 | X7: 6.74 | Z7: Goals Against vs expected | AA7: =SUMPRODUCT(--($E$2:$E$9>$G$2:$G$9)) | AB7: =SUMPRODUCT(--($E$2:$E$9<$G$2:$G$9))
A8: 2026-09-19 | B8: Hibernian | C8: Away | D8: 1 | E8: 1 | F8: 1.07 | G8: 1.87 | H8: 0.7 | I8: 1.4 | J8: -0.37 | K8: -0.47 | L8: -0.5 | M8: -0.12 | N8: -0.79 | O8: -0.56 | P8: -0.73 | Q8: -0.25 | R8: =(H8-I8)-(F8-G8) | S8: =(H8+I8)-(F8+G8) | T8: 0.84 | U8: 0.87 | V8: -0.03 | W8: 6.69 | X8: 7.61 | Z8: For: Above = beat expectation. Against: Above = conceded more than expected (worse).
A9: 2026-10-11 | B9: St Johnstone | C9: Home | D9: 0 | E9: 1 | F9: 1.5 | G9: 1.16 | H9: 1.69 | I9: 1.25 | J9: 0.19 | K9: 0.09 | L9: -0.35 | M9: -0.19 | N9: 0.08 | O9: 0.04 | P9: -0.61 | Q9: -0.31 | R9: =(H9-I9)-(F9-G9) | S9: =(H9+I9)-(F9+G9) | T9: 1.67 | U9: 1.61 | V9: 0.06 | W9: 8.36 | X9: 9.21 | Z9: Chart data: Against figures are stored as negatives so they plot below the zero line.
Z10: Gameweek | AA10: Goals For | AB10: Goals Against | AC10: Expected Goals For | AD10: Expected Goals Against
A11: Season summary | Z11: MW1 | AA11: =D2 | AB11: =-E2 | AC11: =F2 | AD11: =-G2
A12: Matches played | E12: =COUNTA(A2:A9) | Z12: MW2 | AA12: =D3 | AB12: =-E3 | AC12: =F3 | AD12: =-G3
A13: Total goals for | E13: =SUM(D2:D9) | Z13: MW3 | AA13: =D4 | AB13: =-E4 | AC13: =F4 | AD13: =-G4
A14: Total goals against | E14: =SUM(E2:E9) | Z14: MW4 | AA14: =D5 | AB14: =-E5 | AC14: =F5 | AD14: =-G5
A15: Avg xG Delta (For) | E15: =AVERAGE(J2:J9) | Z15: MW5 | AA15: =D6 | AB15: =-E6 | AC15: =F6 | AD15: =-G6
A16: Median xG Delta (For) | E16: =MEDIAN(J2:J9) | Z16: MW6 | AA16: =D7 | AB16: =-E7 | AC16: =F7 | AD16: =-G7
A17: Avg xG Delta (Against) | E17: =AVERAGE(K2:K9) | Z17: MW7 | AA17: =D8 | AB17: =-E8 | AC17: =F8 | AD17: =-G8
A18: Median xG Delta (Against) | E18: =MEDIAN(K2:K9) | Z18: MW8 | AA18: =D9 | AB18: =-E9 | AC18: =F9 | AD18: =-G9
A19: Avg xG Delta (For, Adj) | E19: =AVERAGE(N2:N9)
A20: Median xG Delta (For, Adj) | E20: =MEDIAN(N2:N9)
A21: Avg xG Delta (Against, Adj) | E21: =AVERAGE(O2:O9)
A22: Median xG Delta (Against, Adj) | E22: =MEDIAN(O2:O9)
A23: Avg Supremacy Delta | E23: =AVERAGE(R2:R9) | AF23: Aberdeen: closing odds to win, by opponent (league table order)
A24: Median Supremacy Delta | E24: =MEDIAN(R2:R9) | AF24: League Table | AG24: Home Odds | AH24: Away Odds
A25: Avg Total xG Delta | E25: =AVERAGE(S2:S9) | AF25: 1. Celtic | AH25: 12
A26: Median Total xG Delta | E26: =MEDIAN(S2:S9) | AF26: 2. Rangers | AG26: 4
A27: Current form (last 6, For) | E27: =L9 | AF27: 3. Heart of Midlothian | AG27: 2.9
A28: Current form (last 6, Against) | E28: =M9 | AF28: 4. Dundee | AH28: 2.38
A29: Current form (last 6, For, Adj) | E29: =P9 | AF29: 5. St Johnstone | AG29: 1.95
A30: Current form (last 6, Against, Adj) | E30: =Q9 | AF30: 6. Dundee United
A31: Total xPts (Actual) | E31: =SUM(T2:T9) | AF31: 7. St Mirren
A32: Total xPts (Market) | E32: =SUM(U2:U9) | AF32: 8. Aberdeen
A33: Avg xPts Delta | E33: =AVERAGE(V2:V9) | AF33: 9. Motherwell | AH33: 4
AF34: 10. Hibernian | AH34: 4.5
A35: Home / Away split | AF35: 11. Falkirk
A36: Venue | B36: Matches | C36: GF | D36: GA | E36: Avg Supremacy | F36: Median Supremacy | G36: Avg Total xG Delta | H36: Median Total xG Delta | AF36: 12. Kilmarnock | AG36: 1.65
A37: Home | B37: 4 | C37: 2 | D37: 3 | E37: -0.15 | F37: -0.36 | G37: 0.15 | H37: -0.14
A38: Away | B38: 4 | C38: 5 | D38: 6 | E38: -0.11 | F38: 0.03 | G38: -0.6 | H38: -0.52 | AF38: Won
A39: Total | B39: 8 | C39: 7 | D39: 9 | E39: -0.13 | F39: 0.03 | G39: -0.22 | H39: -0.39 | AF39: Drew
AF40: Lost
...

Sheet Celtic
A1: Date | B1: Opponent | C1: Venue | D1: Goals For | E1: Goals Against | F1: xG Pre-Match (For) | G1: xG Pre-Match (Against) | H1: xG Actual (For) | I1: xG Actual (Against) | J1: xG Delta (For) | K1: xG Delta (Against) | L1: Rolling Delta (For) | M1: Rolling Delta (Against) | N1: xG Delta (For, Adj) | O1: xG Delta (Against, Adj) | P1: Rolling Delta (For, Adj) | Q1: Rolling Delta (Against, Adj) | R1: Supremacy Delta | S1: Match Total xG Delta | T1: xPts (Actual) | U1: xPts (Market) | V1: xPts Delta | W1: xPts (Actual, Cum.) | X1: xPts (Market, Cum.) | Z1: Goals vs expected
A2: 2026-08-03 | B2: Dundee | C2: Home | D2: 1 | E2: 0 | F2: 2.83 | G2: 0.81 | H2: 2.25 | I2: 0.49 | J2: -0.58 | K2: -0.32 | L2: -0.58 | M2: -0.32 | N2: -0.51 | O2: -0.52 | P2: -0.51 | Q2: -0.52 | R2: =(H2-I2)-(F2-G2) | S2: =(H2+I2)-(F2+G2) | T2: 2.49 | U2: 2.5 | V2: -0.01 | W2: 2.49 | X2: 2.5 | Z2: Expected = the pre-match market xG (what the odds implied) for each side.
A3: 2026-08-09 | B3: Kilmarnock | C3: Away | D3: 5 | E3: 1 | F3: 2.4 | G3: 0.98 | H3: 5.44 | I3: 0.98 | J3: 3.04 | K3: 0 | L3: 1.23 | M3: -0.16 | N3: 3.16 | O3: 0.07 | P3: 1.33 | Q3: -0.22 | R3: =(H3-I3)-(F3-G3) | S3: =(H3+I3)-(F3+G3) | T3: 2.82 | U3: 2.24 | V3: 0.58 | W3: 5.3 | X3: 4.74 | Z3: Games vs expected | AA3: Above | AB3: Below
A4: 2026-08-29 | B4: Falkirk | C4: Home | D4: 2 | E4: 1 | F4: 2.78 | G4: 0.82 | H4: 3.45 | I4: 0.57 | J4: 0.67 | K4: -0.25 | L4: 1.04 | M4: -0.19 | N4: 0.61 | O4: -0.27 | P4: 1.09 | Q4: -0.24 | R4: =(H4-I4)-(F4-G4) | S4: =(H4+I4)-(F4+G4) | T4: 2.76 | U4: 2.48 | V4: 0.28 | W4: 8.06 | X4: 7.22 | Z4: xG For vs expected | AA4: =COUNTIF($J$2:$J$9,">0") | AB4: =COUNTIF($J$2:$J$9,"<0")
A5: 2026-09-02 | B5: Aberdeen | C5: Home | D5: 3 | E5: 0 | F5: 2.74 | G5: 0.8 | H5: 2.67 | I5: 0.68 | J5: -0.07 | K5: -0.12 | L5: 0.77 | M5: -0.17 | N5: -0.02 | O5: 0.07 | P5: 0.81 | Q5: -0.16 | R5: =(H5-I5)-(F5-G5) | S5: =(H5+I5)-(F5+G5) | T5: 2.52 | U5: 2.48 | V5: 0.04 | W5: 10.58 | X5: 9.69 | Z5: xG Against vs expected | AA5: =COUNTIF($K$2:$K$9,">0") | AB5: =COUNTIF($K$2:$K$9,"<0")
A6: 2026-09-05 | B6: St Mirren | C6: Away | D6: 2 | E6: 1 | F6: 2.25 | G6: 1.03 | H6: 3.19 | I6: 1.95 | J6: 0.94 | K6: 0.92 | L6: 0.8 | M6: 0.05 | N6: 0.81 | O6: 0.75 | P6: 0.81 | Q6: 0.02 | R6: =(H6-I6)-(F6-G6) | S6: =(H6+I6)-(F6+G6) | T6: 2.03 | U6: 2.13 | V6: -0.1 | W6: 12.61 | X6: 11.83 | Z6: Goals For vs expected | AA6: =SUMPRODUCT(--($D$2:$D$9>$F$2:$F$9)) | AB6: =SUMPRODUCT(--($D$2:$D$9<$F$2:$F$9))
A7: 2026-09-09 | B7: St Johnstone | C7: Away | D7: 1 | E7: 0 | F7: 2.24 | G7: 1.05 | H7: 1.8 | I7: 0.69 | J7: -0.44 | K7: -0.36 | L7: 0.59 | M7: -0.02 | N7: -0.64 | O7: -0.48 | P7: 0.57 | Q7: -0.06 | R7: =(H7-I7)-(F7-G7) | S7: =(H7+I7)-(F7+G7) | T7: 2.14 | U7: 2.12 | V7: 0.03 | W7: 14.75 | X7: 13.95 | Z7: Goals Against vs expected | AA7: =SUMPRODUCT(--($E$2:$E$9>$G$2:$G$9)) | AB7: =SUMPRODUCT(--($E$2:$E$9<$G$2:$G$9))
A8: 2026-09-20 | B8: Rangers | C8: Home | D8: 0 | E8: 1 | F8: 1.73 | G8: 1.44 | H8: 0.39 | I8: 1.75 | J8: -1.34 | K8: 0.31 | L8: 0.47 | M8: 0.08 | N8: -1.51 | O8: 0.29 | P8: 0.4 | Q8: 0.07 | R8: =(H8-I8)-(F8-G8) | S8: =(H8+I8)-(F8+G8) | T8: 0.44 | U8: 1.57 | V8: -1.13 | W8: 15.2 | X8: 15.51 | Z8: For: Above = beat expectation. Against: Above = conceded more than expected (worse).
A9: 2026-10-11 | B9: Motherwell | C9: Away | D9: 2 | E9: 0 | F9: 2.19 | G9: 1.16 | H9: 2.85 | I9: 1.05 | J9: 0.66 | K9: -0.11 | L9: 0.07 | M9: 0.06 | N9: 0.32 | O9: -0.21 | P9: -0.07 | Q9: 0.02 | R9: =(H9-I9)-(F9-G9) | S9: =(H9+I9)-(F9+G9) | T9: 2.38 | U9: 2.02 | V9: 0.36 | W9: 17.57 | X9: 17.53 | Z9: Chart data: Against figures are stored as negatives so they plot below the zero line.
Z10: Gameweek | AA10: Goals For | AB10: Goals Against | AC10: Expected Goals For | AD10: Expected Goals Against
A11: Season summary | Z11: MW1 | AA11: =D2 | AB11: =-E2 | AC11: =F2 | AD11: =-G2
A12: Matches played | E12: =COUNTA(A2:A9) | Z12: MW2 | AA12: =D3 | AB12: =-E3 | AC12: =F3 | AD12: =-G3
A13: Total goals for | E13: =SUM(D2:D9) | Z13: MW3 | AA13: =D4 | AB13: =-E4 | AC13: =F4 | AD13: =-G4
A14: Total goals against | E14: =SUM(E2:E9) | Z14: MW4 | AA14: =D5 | AB14: =-E5 | AC14: =F5 | AD14: =-G5
A15: Avg xG Delta (For) | E15: =AVERAGE(J2:J9) | Z15: MW5 | AA15: =D6 | AB15: =-E6 | AC15: =F6 | AD15: =-G6
A16: Median xG Delta (For) | E16: =MEDIAN(J2:J9) | Z16: MW6 | AA16: =D7 | AB16: =-E7 | AC16: =F7 | AD16: =-G7
A17: Avg xG Delta (Against) | E17: =AVERAGE(K2:K9) | Z17: MW7 | AA17: =D8 | AB17: =-E8 | AC17: =F8 | AD17: =-G8
A18: Median xG Delta (Against) | E18: =MEDIAN(K2:K9) | Z18: MW8 | AA18: =D9 | AB18: =-E9 | AC18: =F9 | AD18: =-G9
A19: Avg xG Delta (For, Adj) | E19: =AVERAGE(N2:N9)
A20: Median xG Delta (For, Adj) | E20: =MEDIAN(N2:N9)
A21: Avg xG Delta (Against, Adj) | E21: =AVERAGE(O2:O9)
A22: Median xG Delta (Against, Adj) | E22: =MEDIAN(O2:O9)
A23: Avg Supremacy Delta | E23: =AVERAGE(R2:R9) | AF23: Celtic: closing odds to win, by opponent (league table order)
A24: Median Supremacy Delta | E24: =MEDIAN(R2:R9) | AF24: League Table | AG24: Home Odds | AH24: Away Odds
A25: Avg Total xG Delta | E25: =AVERAGE(S2:S9) | AF25: 1. Celtic
A26: Median Total xG Delta | E26: =MEDIAN(S2:S9) | AF26: 2. Rangers | AG26: 2.1
A27: Current form (last 6, For) | E27: =L9 | AF27: 3. Heart of Midlothian
A28: Current form (last 6, Against) | E28: =M9 | AF28: 4. Dundee | AG28: 1.11
A29: Current form (last 6, For, Adj) | E29: =P9 | AF29: 5. St Johnstone | AH29: 1.5
A30: Current form (last 6, Against, Adj) | E30: =Q9 | AF30: 6. Dundee United
A31: Total xPts (Actual) | E31: =SUM(T2:T9) | AF31: 7. St Mirren | AH31: 1.36
A32: Total xPts (Market) | E32: =SUM(U2:U9) | AF32: 8. Aberdeen | AG32: 1.2
A33: Avg xPts Delta | E33: =AVERAGE(V2:V9) | AF33: 9. Motherwell | AH33: 1.5
AF34: 10. Hibernian
A35: Home / Away split | AF35: 11. Falkirk | AG35: 1.2
A36: Venue | B36: Matches | C36: GF | D36: GA | E36: Avg Supremacy | F36: Median Supremacy | G36: Avg Total xG Delta | H36: Median Total xG Delta | AF36: 12. Kilmarnock | AH36: 1.33
A37: Home | B37: 4 | C37: 6 | D37: 2 | E37: -0.23 | F37: -0.11 | G37: -0.43 | H37: -0.55
A38: Away | B38: 4 | C38: 10 | D38: 2 | E38: 0.94 | F38: 0.4 | G38: 1.16 | H38: 1.21 | AF38: Won
A39: Total | B39: 8 | C39: 16 | D39: 4 | E39: 0.35 | F39: 0.04 | G39: 0.37 | H39: 0.11 | AF39: Drew
AF40: Lost
...

Sheet Dundee
A1: Date | B1: Opponent | C1: Venue | D1: Goals For | E1: Goals Against | F1: xG Pre-Match (For) | G1: xG Pre-Match (Against) | H1: xG Actual (For) | I1: xG Actual (Against) | J1: xG Delta (For) | K1: xG Delta (Against) | L1: Rolling Delta (For) | M1: Rolling Delta (Against) | N1: xG Delta (For, Adj) | O1: xG Delta (Against, Adj) | P1: Rolling Delta (For, Adj) | Q1: Rolling Delta (Against, Adj) | R1: Supremacy Delta | S1: Match Total xG Delta | T1: xPts (Actual) | U1: xPts (Market) | V1: xPts Delta | W1: xPts (Actual, Cum.) | X1: xPts (Market, Cum.) | Z1: Goals vs expected
A2: 2026-08-03 | B2: Celtic | C2: Away | D2: 0 | E2: 1 | F2: 0.81 | G2: 2.83 | H2: 0.49 | I2: 2.25 | J2: -0.32 | K2: -0.58 | L2: -0.32 | M2: -0.58 | N2: -0.37 | O2: -1.08 | P2: -0.37 | Q2: -1.08 | R2: =(H2-I2)-(F2-G2) | S2: =(H2+I2)-(F2+G2) | T2: 0.35 | U2: 0.37 | V2: -0.01 | W2: 0.35 | X2: 0.37 | Z2: Expected = the pre-match market xG (what the odds implied) for each side.
A3: 2026-08-08 | B3: Aberdeen | C3: Home | D3: 2 | E3: 0 | F3: 1.34 | G3: 1.41 | H3: 1.83 | I3: 0.71 | J3: 0.49 | K3: -0.7 | L3: 0.08 | M3: -0.64 | N3: 0.61 | O3: -0.6 | P3: 0.12 | Q3: -0.84 | R3: =(H3-I3)-(F3-G3) | S3: =(H3+I3)-(F3+G3) | T3: 2.14 | U3: 1.33 | V3: 0.81 | W3: 2.5 | X3: 1.7 | Z3: Games vs expected | AA3: Above | AB3: Below
A4: 2026-08-22 | B4: Dundee United | C4: Away | D4: 2 | E4: 0 | F4: 1.23 | G4: 1.54 | H4: 1.43 | I4: 1.19 | J4: 0.2 | K4: -0.35 | L4: 0.12 | M4: -0.54 | N4: 0.41 | O4: -0.73 | P4: 0.22 | Q4: -0.8 | R4: =(H4-I4)-(F4-G4) | S4: =(H4+I4)-(F4+G4) | T4: 1.54 | U4: 1.16 | V4: 0.38 | W4: 4.04 | X4: 2.86 | Z4: xG For vs expected | AA4: =COUNTIF($J$2:$J$9,">0") | AB4: =COUNTIF($J$2:$J$9,"<0")
A5: 2026-08-30 | B5: Hibernian | C5: Home | D5: 1 | E5: 2 | F5: 1.22 | G5: 1.51 | H5: 1.01 | I5: 2.33 | J5: -0.21 | K5: 0.82 | L5: 0.04 | M5: -0.2 | N5: -0.61 | O5: 0.91 | P5: 0.01 | Q5: -0.37 | R5: =(H5-I5)-(F5-G5) | S5: =(H5+I5)-(F5+G5) | T5: 0.63 | U5: 1.17 | V5: -0.54 | W5: 4.66 | X5: 4.03 | Z5: xG Against vs expected | AA5: =COUNTIF($K$2:$K$9,">0") | AB5: =COUNTIF($K$2:$K$9,"<0")
A6: 2026-09-02 | B6: St Johnstone | C6: Home | D6: 1 | E6: 1 | F6: 1.37 | G6: 1.37 | H6: 2.04 | I6: 1.07 | J6: 0.67 | K6: -0.3 | L6: 0.17 | M6: -0.22 | N6: 0.63 | O6: -0.41 | P6: 0.13 | Q6: -0.38 | R6: =(H6-I6)-(F6-G6) | S6: =(H6+I6)-(F6+G6) | T6: 2 | U6: 1.37 | V6: 0.63 | W6: 6.67 | X6: 5.4 | Z6: Goals For vs expected | AA6: =SUMPRODUCT(--($D$2:$D$9>$F$2:$F$9)) | AB6: =SUMPRODUCT(--($D$2:$D$9<$F$2:$F$9))
A7: 2026-09-06 | B7: Heart of Midlothian | C7: Away | D7: 1 | E7: 2 | F7: 0.96 | G7: 2.12 | H7: 0.42 | I7: 1.92 | J7: -0.54 | K7: -0.2 | L7: 0.05 | M7: -0.22 | N7: -0.74 | O7: -0.48 | P7: -0.01 | Q7: -0.4 | R7: =(H7-I7)-(F7-G7) | S7: =(H7+I7)-(F7+G7) | T7: 0.41 | U7: 0.68 | V7: -0.28 | W7: 7.07 | X7: 6.08 | Z7: Goals Against vs expected | AA7: =SUMPRODUCT(--($E$2:$E$9>$G$2:$G$9)) | AB7: =SUMPRODUCT(--($E$2:$E$9<$G$2:$G$9))
A8: 2026-09-19 | B8: Motherwell | C8: Home | D8: 2 | E8: 1 | F8: 1.31 | G8: 1.54 | H8: 1.38 | I8: 1.1 | J8: 0.07 | K8: -0.44 | L8: 0.11 | M8: -0.19 | N8: -0.35 | O8: -0.59 | P8: -0.01 | Q8: -0.32 | R8: =(H8-I8)-(F8-G8) | S8: =(H8+I8)-(F8+G8) | T8: 1.57 | U8: 1.22 | V8: 0.34 | W8: 8.64 | X8: 7.31 | Z8: For: Above = beat expectation. Against: Above = conceded more than expected (worse).
A9: 2026-10-10 | B9: Falkirk | C9: Away | D9: 2 | E9: 1 | F9: 1.19 | G9: 1.66 | H9: 1.9 | I9: 2.31 | J9: 0.71 | K9: 0.65 | L9: 0.15 | M9: 0.03 | N9: 0.66 | O9: 0.77 | P9: 0 | Q9: -0.09 | R9: =(H9-I9)-(F9-G9) | S9: =(H9+I9)-(F9+G9) | T9: 1.17 | U9: 1.06 | V9: 0.11 | W9: 9.81 | X9: 8.37 | Z9: Chart data: Against figures are stored as negatives so they plot below the zero line.
