Workbook

Sheet About This Report
A1: About This Report
A3: Sheets in this workbook
A4: League Table - standard standings from every played match.
A5: Overview - a deliberately narrow at-a-glance summary of each team's core xG/xPts form, sorted by Avg xG Delta (For), best first. Medians, adjusted current form, and a couple of stats already shown elsewhere are left off - see the team tabs and the dedicated grid sheets for the full detail.
A6: xPts Table - teams ranked by season-total xPts Delta (actual deserved points minus what the market expected), highest over-performance first - a "truer" table than the real one below since it's driven by chance quality rather than which chances actually went in.
A7: Dashboard - three league-wide charts (xG Delta For, Supremacy Delta, xPts Actual vs Market) so patterns are visible at a glance instead of scrolling through team tabs.
A8: Data Quality - flags fixtures with missing/negative xG or goals, or suspicious exact-0.00 xG on both sides - a first stop before trusting a given run's numbers.
A9: Match Log - the single master data table: one row per fixture (not per team) with every core stat, and an AutoFilter so you can filter by team/venue without hunting through team tabs.
A10: Home & Away Splits - Total/Home/Away average and median supremacy, and Total/Home/Away goals, for every team.
A11: Supremacy Delta / (Home) / (Away) - match-by-match grids of actual vs. expected xG supremacy, each sorted by its own average, highest first.
A12: Total xG Delta - match-by-match grid of how much higher/lower-scoring each match was than the market expected, sorted by its own average, with a Median column at the end.
A13: xPts Delta - match-by-match grid of expected-points over/under-performance, sorted by its own average.
... A22: • The Supremacy Delta (Home) / (Away) grids are literal snapshots (computed once, at report-generation time) rather than live formulas like the full-season grid, since a team's home-only matches aren't a contiguous block of rows on its own sheet. Re-run the pipeline to refresh them.

Sheet League Table
A1: Pos | B1: Team | C1: P | D1: W | E1: D | F1: L | G1: GF | H1: GA | I1: GD | J1: Pts
A2: =ROW()-1 | B2: Salford City | C2: =COUNTIF('Results Data'!$B$2:$B$115,$B2)+COUNTIF('Results Data'!$C$2:$C$115,$B2) | D2: =SUMPRODUCT(('Results Data'!$B$2:$B$115=$B2)*('Results Data'!$D$2:$D$115>'Results Data'!$E$2:$E$115))+SUMPRODUCT(('Results Data'!$C$2:$C$115=$B2)*('Results Data'!$E$2:$E$115>'Results Data'!$D$2:$D$115)) | E2: =SUMPRODUCT(('Results Data'!$B$2:$B$115=$B2)*('Results Data'!$D$2:$D$115='Results Data'!$E$2:$E$115))+SUMPRODUCT(('Results Data'!$C$2:$C$115=$B2)*('Results Data'!$E$2:$E$115='Results Data'!$D$2:$D$115)) | F2: =C2-D2-E2 | G2: =SUMIF('Results Data'!$B$2:$B$115,$B2,'Results Data'!$D$2:$D$115)+SUMIF('Results Data'!$C$2:$C$115,$B2,'Results Data'!$E$2:$E$115) | H2: =SUMIF('Results Data'!$B$2:$B$115,$B2,'Results Data'!$E$2:$E$115)+SUMIF('Results Data'!$C$2:$C$115,$B2,'Results Data'!$D$2:$D$115) | I2: =G2-H2 | J2: =D2*3+E2
A3: =ROW()-1 | B3: Barnet | C3: =COUNTIF('Results Data'!$B$2:$B$115,$B3)+COUNTIF('Results Data'!$C$2:$C$115,$B3) | D3: =SUMPRODUCT(('Results Data'!$B$2:$B$115=$B3)*('Results Data'!$D$2:$D$115>'Results Data'!$E$2:$E$115))+SUMPRODUCT(('Results Data'!$C$2:$C$115=$B3)*('Results Data'!$E$2:$E$115>'Results Data'!$D$2:$D$115)) | E3: =SUMPRODUCT(('Results Data'!$B$2:$B$115=$B3)*('Results Data'!$D$2:$D$115='Results Data'!$E$2:$E$115))+SUMPRODUCT(('Results Data'!$C$2:$C$115=$B3)*('Results Data'!$E$2:$E$115='Results Data'!$D$2:$D$115)) | F3: =C3-D3-E3 | G3: =SUMIF('Results Data'!$B$2:$B$115,$B3,'Results Data'!$D$2:$D$115)+SUMIF('Results Data'!$C$2:$C$115,$B3,'Results Data'!$E$2:$E$115) | H3: =SUMIF('Results Data'!$B$2:$B$115,$B3,'Results Data'!$E$2:$E$115)+SUMIF('Results Data'!$C$2:$C$115,$B3,'Results Data'!$D$2:$D$115) | I3: =G3-H3 | J3: =D3*3+E3
A4: =ROW()-1 | B4: Crewe Alexandra | C4: =COUNTIF('Results Data'!$B$2:$B$115,$B4)+COUNTIF('Results Data'!$C$2:$C$115,$B4) | D4: =SUMPRODUCT(('Results Data'!$B$2:$B$115=$B4)*('Results Data'!$D$2:$D$115>'Results Data'!$E$2:$E$115))+SUMPRODUCT(('Results Data'!$C$2:$C$115=$B4)*('Results Data'!$E$2:$E$115>'Results Data'!$D$2:$D$115)) | E4: =SUMPRODUCT(('Results Data'!$B$2:$B$115=$B4)*('Results Data'!$D$2:$D$115='Results Data'!$E$2:$E$115))+SUMPRODUCT(('Results Data'!$C$2:$C$115=$B4)*('Results Data'!$E$2:$E$115='Results Data'!$D$2:$D$115)) | F4: =C4-D4-E4 | G4: =SUMIF('Results Data'!$B$2:$B$115,$B4,'Results Data'!$D$2:$D$115)+SUMIF('Results Data'!$C$2:$C$115,$B4,'Results Data'!$E$2:$E$115) | H4: =SUMIF('Results Data'!$B$2:$B$115,$B4,'Results Data'!$E$2:$E$115)+SUMIF('Results Data'!$C$2:$C$115,$B4,'Results Data'!$D$2:$D$115) | I4: =G4-H4 | J4: =D4*3+E4
A5: =ROW()-1 | B5: Gillingham | C5: =COUNTIF('Results Data'!$B$2:$B$115,$B5)+COUNTIF('Results Data'!$C$2:$C$115,$B5) | D5: =SUMPRODUCT(('Results Data'!$B$2:$B$115=$B5)*('Results Data'!$D$2:$D$115>'Results Data'!$E$2:$E$115))+SUMPRODUCT(('Results Data'!$C$2:$C$115=$B5)*('Results Data'!$E$2:$E$115>'Results Data'!$D$2:$D$115)) | E5: =SUMPRODUCT(('Results Data'!$B$2:$B$115=$B5)*('Results Data'!$D$2:$D$115='Results Data'!$E$2:$E$115))+SUMPRODUCT(('Results Data'!$C$2:$C$115=$B5)*('Results Data'!$E$2:$E$115='Results Data'!$D$2:$D$115)) | F5: =C5-D5-E5 | G5: =SUMIF('Results Data'!$B$2:$B$115,$B5,'Results Data'!$D$2:$D$115)+SUMIF('Results Data'!$C$2:$C$115,$B5,'Results Data'!$E$2:$E$115) | H5: =SUMIF('Results Data'!$B$2:$B$115,$B5,'Results Data'!$E$2:$E$115)+SUMIF('Results Data'!$C$2:$C$115,$B5,'Results Data'!$D$2:$D$115) | I5: =G5-H5 | J5: =D5*3+E5
A6: =ROW()-1 | B6: York | C6: =COUNTIF('Results Data'!$B$2:$B$115,$B6)+COUNTIF('Results Data'!$C$2:$C$115,$B6) | D6: =SUMPRODUCT(('Results Data'!$B$2:$B$115=$B6)*('Results Data'!$D$2:$D$115>'Results Data'!$E$2:$E$115))+SUMPRODUCT(('Results Data'!$C$2:$C$115=$B6)*('Results Data'!$E$2:$E$115>'Results Data'!$D$2:$D$115)) | E6: =SUMPRODUCT(('Results Data'!$B$2:$B$115=$B6)*('Results Data'!$D$2:$D$115='Results Data'!$E$2:$E$115))+SUMPRODUCT(('Results Data'!$C$2:$C$115=$B6)*('Results Data'!$E$2:$E$115='Results Data'!$D$2:$D$115)) | F6: =C6-D6-E6 | G6: =SUMIF('Results Data'!$B$2:$B$115,$B6,'Results Data'!$D$2:$D$115)+SUMIF('Results Data'!$C$2:$C$115,$B6,'Results Data'!$E$2:$E$115) | H6: =SUMIF('Results Data'!$B$2:$B$115,$B6,'Results Data'!$E$2:$E$115)+SUMIF('Results Data'!$C$2:$C$115,$B6,'Results Data'!$D$2:$D$115) | I6: =G6-H6 | J6: =D6*3+E6
A7: =ROW()-1 | B7: Walsall | C7: =COUNTIF('Results Data'!$B$2:$B$115,$B7)+COUNTIF('Results Data'!$C$2:$C$115,$B7) | D7: =SUMPRODUCT(('Results Data'!$B$2:$B$115=$B7)*('Results Data'!$D$2:$D$115>'Results Data'!$E$2:$E$115))+SUMPRODUCT(('Results Data'!$C$2:$C$115=$B7)*('Results Data'!$E$2:$E$115>'Results Data'!$D$2:$D$115)) | E7: =SUMPRODUCT(('Results Data'!$B$2:$B$115=$B7)*('Results Data'!$D$2:$D$115='Results Data'!$E$2:$E$115))+SUMPRODUCT(('Results Data'!$C$2:$C$115=$B7)*('Results Data'!$E$2:$E$115='Results Data'!$D$2:$D$115)) | F7: =C7-D7-E7 | G7: =SUMIF('Results Data'!$B$2:$B$115,$B7,'Results Data'!$D$2:$D$115)+SUMIF('Results Data'!$C$2:$C$115,$B7,'Results Data'!$E$2:$E$115) | H7: =SUMIF('Results Data'!$B$2:$B$115,$B7,'Results Data'!$E$2:$E$115)+SUMIF('Results Data'!$C$2:$C$115,$B7,'Results Data'!$D$2:$D$115) | I7: =G7-H7 | J7: =D7*3+E7
A8: =ROW()-1 | B8: Chesterfield | C8: =COUNTIF('Results Data'!$B$2:$B$115,$B8)+COUNTIF('Results Data'!$C$2:$C$115,$B8) | D8: =SUMPRODUCT(('Results Data'!$B$2:$B$115=$B8)*('Results Data'!$D$2:$D$115>'Results Data'!$E$2:$E$115))+SUMPRODUCT(('Results Data'!$C$2:$C$115=$B8)*('Results Data'!$E$2:$E$115>'Results Data'!$D$2:$D$115)) | E8: =SUMPRODUCT(('Results Data'!$B$2:$B$115=$B8)*('Results Data'!$D$2:$D$115='Results Data'!$E$2:$E$115))+SUMPRODUCT(('Results Data'!$C$2:$C$115=$B8)*('Results Data'!$E$2:$E$115='Results Data'!$D$2:$D$115)) | F8: =C8-D8-E8 | G8: =SUMIF('Results Data'!$B$2:$B$115,$B8,'Results Data'!$D$2:$D$115)+SUMIF('Results Data'!$C$2:$C$115,$B8,'Results Data'!$E$2:$E$115) | H8: =SUMIF('Results Data'!$B$2:$B$115,$B8,'Results Data'!$E$2:$E$115)+SUMIF('Results Data'!$C$2:$C$115,$B8,'Results Data'!$D$2:$D$115) | I8: =G8-H8 | J8: =D8*3+E8
A9: =ROW()-1 | B9: Cheltenham Town | C9: =COUNTIF('Results Data'!$B$2:$B$115,$B9)+COUNTIF('Results Data'!$C$2:$C$115,$B9) | D9: =SUMPRODUCT(('Results Data'!$B$2:$B$115=$B9)*('Results Data'!$D$2:$D$115>'Results Data'!$E$2:$E$115))+SUMPRODUCT(('Results Data'!$C$2:$C$115=$B9)*('Results Data'!$E$2:$E$115>'Results Data'!$D$2:$D$115)) | E9: =SUMPRODUCT(('Results Data'!$B$2:$B$115=$B9)*('Results Data'!$D$2:$D$115='Results Data'!$E$2:$E$115))+SUMPRODUCT(('Results Data'!$C$2:$C$115=$B9)*('Results Data'!$E$2:$E$115='Results Data'!$D$2:$D$115)) | F9: =C9-D9-E9 | G9: =SUMIF('Results Data'!$B$2:$B$115,$B9,'Results Data'!$D$2:$D$115)+SUMIF('Results Data'!$C$2:$C$115,$B9,'Results Data'!$E$2:$E$115) | H9: =SUMIF('Results Data'!$B$2:$B$115,$B9,'Results Data'!$E$2:$E$115)+SUMIF('Results Data'!$C$2:$C$115,$B9,'Results Data'!$D$2:$D$115) | I9: =G9-H9 | J9: =D9*3+E9
A10: =ROW()-1 | B10: Bristol Rvs | C10: =COUNTIF('Results Data'!$B$2:$B$115,$B10)+COUNTIF('Results Data'!$C$2:$C$115,$B10) | D10: =SUMPRODUCT(('Results Data'!$B$2:$B$115=$B10)*('Results Data'!$D$2:$D$115>'Results Data'!$E$2:$E$115))+SUMPRODUCT(('Results Data'!$C$2:$C$115=$B10)*('Results Data'!$E$2:$E$115>'Results Data'!$D$2:$D$115)) | E10: =SUMPRODUCT(('Results Data'!$B$2:$B$115=$B10)*('Results Data'!$D$2:$D$115='Results Data'!$E$2:$E$115))+SUMPRODUCT(('Results Data'!$C$2:$C$115=$B10)*('Results Data'!$E$2:$E$115='Results Data'!$D$2:$D$115)) | F10: =C10-D10-E10 | G10: =SUMIF('Results Data'!$B$2:$B$115,$B10,'Results Data'!$D$2:$D$115)+SUMIF('Results Data'!$C$2:$C$115,$B10,'Results Data'!$E$2:$E$115) | H10: =SUMIF('Results Data'!$B$2:$B$115,$B10,'Results Data'!$E$2:$E$115)+SUMIF('Results Data'!$C$2:$C$115,$B10,'Results Data'!$D$2:$D$115) | I10: =G10-H10 | J10: =D10*3+E10
A11: =ROW()-1 | B11: Rochdale | C11: =COUNTIF('Results Data'!$B$2:$B$115,$B11)+COUNTIF('Results Data'!$C$2:$C$115,$B11) | D11: =SUMPRODUCT(('Results Data'!$B$2:$B$115=$B11)*('Results Data'!$D$2:$D$115>'Results Data'!$E$2:$E$115))+SUMPRODUCT(('Results Data'!$C$2:$C$115=$B11)*('Results Data'!$E$2:$E$115>'Results Data'!$D$2:$D$115)) | E11: =SUMPRODUCT(('Results Data'!$B$2:$B$115=$B11)*('Results Data'!$D$2:$D$115='Results Data'!$E$2:$E$115))+SUMPRODUCT(('Results Data'!$C$2:$C$115=$B11)*('Results Data'!$E$2:$E$115='Results Data'!$D$2:$D$115)) | F11: =C11-D11-E11 | G11: =SUMIF('Results Data'!$B$2:$B$115,$B11,'Results Data'!$D$2:$D$115)+SUMIF('Results Data'!$C$2:$C$115,$B11,'Results Data'!$E$2:$E$115) | H11: =SUMIF('Results Data'!$B$2:$B$115,$B11,'Results Data'!$E$2:$E$115)+SUMIF('Results Data'!$C$2:$C$115,$B11,'Results Data'!$D$2:$D$115) | I11: =G11-H11 | J11: =D11*3+E11
A12: =ROW()-1 | B12: Grimsby Town | C12: =COUNTIF('Results Data'!$B$2:$B$115,$B12)+COUNTIF('Results Data'!$C$2:$C$115,$B12) | D12: =SUMPRODUCT(('Results Data'!$B$2:$B$115=$B12)*('Results Data'!$D$2:$D$115>'Results Data'!$E$2:$E$115))+SUMPRODUCT(('Results Data'!$C$2:$C$115=$B12)*('Results Data'!$E$2:$E$115>'Results Data'!$D$2:$D$115)) | E12: =SUMPRODUCT(('Results Data'!$B$2:$B$115=$B12)*('Results Data'!$D$2:$D$115='Results Data'!$E$2:$E$115))+SUMPRODUCT(('Results Data'!$C$2:$C$115=$B12)*('Results Data'!$E$2:$E$115='Results Data'!$D$2:$D$115)) | F12: =C12-D12-E12 | G12: =SUMIF('Results Data'!$B$2:$B$115,$B12,'Results Data'!$D$2:$D$115)+SUMIF('Results Data'!$C$2:$C$115,$B12,'Results Data'!$E$2:$E$115) | H12: =SUMIF('Results Data'!$B$2:$B$115,$B12,'Results Data'!$E$2:$E$115)+SUMIF('Results Data'!$C$2:$C$115,$B12,'Results Data'!$D$2:$D$115) | I12: =G12-H12 | J12: =D12*3+E12
A13: =ROW()-1 | B13: Newport County | C13: =COUNTIF('Results Data'!$B$2:$B$115,$B13)+COUNTIF('Results Data'!$C$2:$C$115,$B13) | D13: =SUMPRODUCT(('Results Data'!$B$2:$B$115=$B13)*('Results Data'!$D$2:$D$115>'Results Data'!$E$2:$E$115))+SUMPRODUCT(('Results Data'!$C$2:$C$115=$B13)*('Results Data'!$E$2:$E$115>'Results Data'!$D$2:$D$115)) | E13: =SUMPRODUCT(('Results Data'!$B$2:$B$115=$B13)*('Results Data'!$D$2:$D$115='Results Data'!$E$2:$E$115))+SUMPRODUCT(('Results Data'!$C$2:$C$115=$B13)*('Results Data'!$E$2:$E$115='Results Data'!$D$2:$D$115)) | F13: =C13-D13-E13 | G13: =SUMIF('Results Data'!$B$2:$B$115,$B13,'Results Data'!$D$2:$D$115)+SUMIF('Results Data'!$C$2:$C$115,$B13,'Results Data'!$E$2:$E$115) | H13: =SUMIF('Results Data'!$B$2:$B$115,$B13,'Results Data'!$E$2:$E$115)+SUMIF('Results Data'!$C$2:$C$115,$B13,'Results Data'!$D$2:$D$115) | I13: =G13-H13 | J13: =D13*3+E13
... A25: =ROW()-1 | B25: Crawley Town | C25: =COUNTIF('Results Data'!$B$2:$B$115,$B25)+COUNTIF('Results Data'!$C$2:$C$115,$B25) | D25: =SUMPRODUCT(('Results Data'!$B$2:$B$115=$B25)*('Results Data'!$D$2:$D$115>'Results Data'!$E$2:$E$115))+SUMPRODUCT(('Results Data'!$C$2:$C$115=$B25)*('Results Data'!$E$2:$E$115>'Results Data'!$D$2:$D$115)) | E25: =SUMPRODUCT(('Results Data'!$B$2:$B$115=$B25)*('Results Data'!$D$2:$D$115='Results Data'!$E$2:$E$115))+SUMPRODUCT(('Results Data'!$C$2:$C$115=$B25)*('Results Data'!$E$2:$E$115='Results Data'!$D$2:$D$115)) | F25: =C25-D25-E25 | G25: =SUMIF('Results Data'!$B$2:$B$115,$B25,'Results Data'!$D$2:$D$115)+SUMIF('Results Data'!$C$2:$C$115,$B25,'Results Data'!$E$2:$E$115) | H25: =SUMIF('Results Data'!$B$2:$B$115,$B25,'Results Data'!$E$2:$E$115)+SUMIF('Results Data'!$C$2:$C$115,$B25,'Results Data'!$D$2:$D$115) | I25: =G25-H25 | J25: =D25*3+E25

Sheet Overview
A1: Team | B1: Matches Played | C1: Avg xG Delta (For) | D1: Avg xG Delta (Against) | E1: Avg xG Delta (For, Adj) | F1: Avg xG Delta (Against, Adj) | G1: Avg Supremacy Delta | H1: Current Form (6, For) | I1: Current Form (6, Against) | J1: Total xPts (Actual) | K1: Total xPts (Market) | L1: Avg xPts Delta
A2: Chesterfield | B2: ='Chesterfield'!$E$14 | C2: ='Chesterfield'!$E$17 | D2: ='Chesterfield'!$E$19 | E2: ='Chesterfield'!$E$21 | F2: ='Chesterfield'!$E$23 | G2: ='Chesterfield'!$E$25 | H2: ='Chesterfield'!$E$29 | I2: ='Chesterfield'!$E$30 | J2: ='Chesterfield'!$E$33 | K2: ='Chesterfield'!$E$34 | L2: ='Chesterfield'!$E$35
A3: Accrington Stanley | B3: ='Accrington Stanley'!$E$14 | C3: ='Accrington Stanley'!$E$17 | D3: ='Accrington Stanley'!$E$19 | E3: ='Accrington Stanley'!$E$21 | F3: ='Accrington Stanley'!$E$23 | G3: ='Accrington Stanley'!$E$25 | H3: ='Accrington Stanley'!$E$29 | I3: ='Accrington Stanley'!$E$30 | J3: ='Accrington Stanley'!$E$33 | K3: ='Accrington Stanley'!$E$34 | L3: ='Accrington Stanley'!$E$35
A4: Crawley Town | B4: ='Crawley Town'!$E$12 | C4: ='Crawley Town'!$E$15 | D4: ='Crawley Town'!$E$17 | E4: ='Crawley Town'!$E$19 | F4: ='Crawley Town'!$E$21 | G4: ='Crawley Town'!$E$23 | H4: ='Crawley Town'!$E$27 | I4: ='Crawley Town'!$E$28 | J4: ='Crawley Town'!$E$31 | K4: ='Crawley Town'!$E$32 | L4: ='Crawley Town'!$E$33
A5: York | B5: ='York'!$E$13 | C5: ='York'!$E$16 | D5: ='York'!$E$18 | E5: ='York'!$E$20 | F5: ='York'!$E$22 | G5: ='York'!$E$24 | H5: ='York'!$E$28 | I5: ='York'!$E$29 | J5: ='York'!$E$32 | K5: ='York'!$E$33 | L5: ='York'!$E$34
A6: Barnet | B6: ='Barnet'!$E$12 | C6: ='Barnet'!$E$15 | D6: ='Barnet'!$E$17 | E6: ='Barnet'!$E$19 | F6: ='Barnet'!$E$21 | G6: ='Barnet'!$E$23 | H6: ='Barnet'!$E$27 | I6: ='Barnet'!$E$28 | J6: ='Barnet'!$E$31 | K6: ='Barnet'!$E$32 | L6: ='Barnet'!$E$33
A7: Grimsby Town | B7: ='Grimsby Town'!$E$14 | C7: ='Grimsby Town'!$E$17 | D7: ='Grimsby Town'!$E$19 | E7: ='Grimsby Town'!$E$21 | F7: ='Grimsby Town'!$E$23 | G7: ='Grimsby Town'!$E$25 | H7: ='Grimsby Town'!$E$29 | I7: ='Grimsby Town'!$E$30 | J7: ='Grimsby Town'!$E$33 | K7: ='Grimsby Town'!$E$34 | L7: ='Grimsby Town'!$E$35
A8: Rotherham United | B8: ='Rotherham United'!$E$14 | C8: ='Rotherham United'!$E$17 | D8: ='Rotherham United'!$E$19 | E8: ='Rotherham United'!$E$21 | F8: ='Rotherham United'!$E$23 | G8: ='Rotherham United'!$E$25 | H8: ='Rotherham United'!$E$29 | I8: ='Rotherham United'!$E$30 | J8: ='Rotherham United'!$E$33 | K8: ='Rotherham United'!$E$34 | L8: ='Rotherham United'!$E$35
A9: Shrewsbury Town | B9: ='Shrewsbury Town'!$E$14 | C9: ='Shrewsbury Town'!$E$17 | D9: ='Shrewsbury Town'!$E$19 | E9: ='Shrewsbury Town'!$E$21 | F9: ='Shrewsbury Town'!$E$23 | G9: ='Shrewsbury Town'!$E$25 | H9: ='Shrewsbury Town'!$E$29 | I9: ='Shrewsbury Town'!$E$30 | J9: ='Shrewsbury Town'!$E$33 | K9: ='Shrewsbury Town'!$E$34 | L9: ='Shrewsbury Town'!$E$35
A10: Bristol Rvs | B10: ='Bristol Rvs'!$E$14 | C10: ='Bristol Rvs'!$E$17 | D10: ='Bristol Rvs'!$E$19 | E10: ='Bristol Rvs'!$E$21 | F10: ='Bristol Rvs'!$E$23 | G10: ='Bristol Rvs'!$E$25 | H10: ='Bristol Rvs'!$E$29 | I10: ='Bristol Rvs'!$E$30 | J10: ='Bristol Rvs'!$E$33 | K10: ='Bristol Rvs'!$E$34 | L10: ='Bristol Rvs'!$E$35
A11: Walsall | B11: ='Walsall'!$E$13 | C11: ='Walsall'!$E$16 | D11: ='Walsall'!$E$18 | E11: ='Walsall'!$E$20 | F11: ='Walsall'!$E$22 | G11: ='Walsall'!$E$24 | H11: ='Walsall'!$E$28 | I11: ='Walsall'!$E$29 | J11: ='Walsall'!$E$32 | K11: ='Walsall'!$E$33 | L11: ='Walsall'!$E$34
A12: Gillingham | B12: ='Gillingham'!$E$14 | C12: ='Gillingham'!$E$17 | D12: ='Gillingham'!$E$19 | E12: ='Gillingham'!$E$21 | F12: ='Gillingham'!$E$23 | G12: ='Gillingham'!$E$25 | H12: ='Gillingham'!$E$29 | I12: ='Gillingham'!$E$30 | J12: ='Gillingham'!$E$33 | K12: ='Gillingham'!$E$34 | L12: ='Gillingham'!$E$35
A13: Exeter | B13: ='Exeter'!$E$14 | C13: ='Exeter'!$E$17 | D13: ='Exeter'!$E$19 | E13: ='Exeter'!$E$21 | F13: ='Exeter'!$E$23 | G13: ='Exeter'!$E$25 | H13: ='Exeter'!$E$29 | I13: ='Exeter'!$E$30 | J13: ='Exeter'!$E$33 | K13: ='Exeter'!$E$34 | L13: ='Exeter'!$E$35
A14: Newport County | B14: ='Newport County'!$E$14 | C14: ='Newport County'!$E$17 | D14: ='Newport County'!$E$19 | E14: ='Newport County'!$E$21 | F14: ='Newport County'!$E$23 | G14: ='Newport County'!$E$25 | H14: ='Newport County'!$E$29 | I14: ='Newport County'!$E$30 | J14: ='Newport County'!$E$33 | K14: ='Newport County'!$E$34 | L14: ='Newport County'!$E$35
A15: Port Vale | B15: ='Port Vale'!$E$12 | C15: ='Port Vale'!$E$15 | D15: ='Port Vale'!$E$17 | E15: ='Port Vale'!$E$19 | F15: ='Port Vale'!$E$21 | G15: ='Port Vale'!$E$23 | H15: ='Port Vale'!$E$27 | I15: ='Port Vale'!$E$28 | J15: ='Port Vale'!$E$31 | K15: ='Port Vale'!$E$32 | L15: ='Port Vale'!$E$33
A16: Tranmere Rovers | B16: ='Tranmere Rovers'!$E$14 | C16: ='Tranmere Rovers'!$E$17 | D16: ='Tranmere Rovers'!$E$19 | E16: ='Tranmere Rovers'!$E$21 | F16: ='Tranmere Rovers'!$E$23 | G16: ='Tranmere Rovers'!$E$25 | H16: ='Tranmere Rovers'!$E$29 | I16: ='Tranmere Rovers'!$E$30 | J16: ='Tranmere Rovers'!$E$33 | K16: ='Tranmere Rovers'!$E$34 | L16: ='Tranmere Rovers'!$E$35
A17: Cheltenham Town | B17: ='Cheltenham Town'!$E$14 | C17: ='Cheltenham Town'!$E$17 | D17: ='Cheltenham Town'!$E$19 | E17: ='Cheltenham Town'!$E$21 | F17: ='Cheltenham Town'!$E$23 | G17: ='Cheltenham Town'!$E$25 | H17: ='Cheltenham Town'!$E$29 | I17: ='Cheltenham Town'!$E$30 | J17: ='Cheltenham Town'!$E$33 | K17: ='Cheltenham Town'!$E$34 | L17: ='Cheltenham Town'!$E$35
A18: Oldham Athletic | B18: ='Oldham Athletic'!$E$13 | C18: ='Oldham Athletic'!$E$16 | D18: ='Oldham Athletic'!$E$18 | E18: ='Oldham Athletic'!$E$20 | F18: ='Oldham Athletic'!$E$22 | G18: ='Oldham Athletic'!$E$24 | H18: ='Oldham Athletic'!$E$28 | I18: ='Oldham Athletic'!$E$29 | J18: ='Oldham Athletic'!$E$32 | K18: ='Oldham Athletic'!$E$33 | L18: ='Oldham Athletic'!$E$34
A19: Fleetwood Town | B19: ='Fleetwood Town'!$E$14 | C19: ='Fleetwood Town'!$E$17 | D19: ='Fleetwood Town'!$E$19 | E19: ='Fleetwood Town'!$E$21 | F19: ='Fleetwood Town'!$E$23 | G19: ='Fleetwood Town'!$E$25 | H19: ='Fleetwood Town'!$E$29 | I19: ='Fleetwood Town'!$E$30 | J19: ='Fleetwood Town'!$E$33 | K19: ='Fleetwood Town'!$E$34 | L19: ='Fleetwood Town'!$E$35
A20: Colchester United | B20: ='Colchester United'!$E$13 | C20: ='Colchester United'!$E$16 | D20: ='Colchester United'!$E$18 | E20: ='Colchester United'!$E$20 | F20: ='Colchester United'!$E$22 | G20: ='Colchester United'!$E$24 | H20: ='Colchester United'!$E$28 | I20: ='Colchester United'!$E$29 | J20: ='Colchester United'!$E$32 | K20: ='Colchester United'!$E$33 | L20: ='Colchester United'!$E$34
A21: Crewe Alexandra | B21: ='Crewe Alexandra'!$E$14 | C21: ='Crewe Alexandra'!$E$17 | D21: ='Crewe Alexandra'!$E$19 | E21: ='Crewe Alexandra'!$E$21 | F21: ='Crewe Alexandra'!$E$23 | G21: ='Crewe Alexandra'!$E$25 | H21: ='Crewe Alexandra'!$E$29 | I21: ='Crewe Alexandra'!$E$30 | J21: ='Crewe Alexandra'!$E$33 | K21: ='Crewe Alexandra'!$E$34 | L21: ='Crewe Alexandra'!$E$35
A22: Swindon Town | B22: ='Swindon Town'!$E$14 | C22: ='Swindon Town'!$E$17 | D22: ='Swindon Town'!$E$19 | E22: ='Swindon Town'!$E$21 | F22: ='Swindon Town'!$E$23 | G22: ='Swindon Town'!$E$25 | H22: ='Swindon Town'!$E$29 | I22: ='Swindon Town'!$E$30 | J22: ='Swindon Town'!$E$33 | K22: ='Swindon Town'!$E$34 | L22: ='Swindon Town'!$E$35
A23: Salford City | B23: ='Salford City'!$E$14 | C23: ='Salford City'!$E$17 | D23: ='Salford City'!$E$19 | E23: ='Salford City'!$E$21 | F23: ='Salford City'!$E$23 | G23: ='Salford City'!$E$25 | H23: ='Salford City'!$E$29 | I23: ='Salford City'!$E$30 | J23: ='Salford City'!$E$33 | K23: ='Salford City'!$E$34 | L23: ='Salford City'!$E$35
A24: Rochdale | B24: ='Rochdale'!$E$14 | C24: ='Rochdale'!$E$17 | D24: ='Rochdale'!$E$19 | E24: ='Rochdale'!$E$21 | F24: ='Rochdale'!$E$23 | G24: ='Rochdale'!$E$25 | H24: ='Rochdale'!$E$29 | I24: ='Rochdale'!$E$30 | J24: ='Rochdale'!$E$33 | K24: ='Rochdale'!$E$34 | L24: ='Rochdale'!$E$35
A25: Northampton Town | B25: ='Northampton Town'!$E$12 | C25: ='Northampton Town'!$E$15 | D25: ='Northampton Town'!$E$17 | E25: ='Northampton Town'!$E$19 | F25: ='Northampton Town'!$E$21 | G25: ='Northampton Town'!$E$23 | H25: ='Northampton Town'!$E$27 | I25: ='Northampton Town'!$E$28 | J25: ='Northampton Town'!$E$31 | K25: ='Northampton Town'!$E$32 | L25: ='Northampton Town'!$E$33

Sheet xPts Table
A1: Pos | B1: Team | C1: Matches | D1: xPts (Actual) | E1: xPts (Market) | F1: xPts Delta (Total)
A2: 1 | B2: Chesterfield | C2: ='Chesterfield'!$E$14 | D2: ='Chesterfield'!$E$33 | E2: ='Chesterfield'!$E$34 | F2: =D2-E2
A3: 2 | B3: Shrewsbury Town | C3: ='Shrewsbury Town'!$E$14 | D3: ='Shrewsbury Town'!$E$33 | E3: ='Shrewsbury Town'!$E$34 | F3: =D3-E3
A4: 3 | B4: Newport County | C4: ='Newport County'!$E$14 | D4: ='Newport County'!$E$33 | E4: ='Newport County'!$E$34 | F4: =D4-E4
A5: 4 | B5: Accrington Stanley | C5: ='Accrington Stanley'!$E$14 | D5: ='Accrington Stanley'!$E$33 | E5: ='Accrington Stanley'!$E$34 | F5: =D5-E5
A6: 5 | B6: Exeter | C6: ='Exeter'!$E$14 | D6: ='Exeter'!$E$33 | E6: ='Exeter'!$E$34 | F6: =D6-E6
A7: 6 | B7: Rotherham United | C7: ='Rotherham United'!$E$14 | D7: ='Rotherham United'!$E$33 | E7: ='Rotherham United'!$E$34 | F7: =D7-E7
A8: 7 | B8: York | C8: ='York'!$E$13 | D8: ='York'!$E$32 | E8: ='York'!$E$33 | F8: =D8-E8
A9: 8 | B9: Crawley Town | C9: ='Crawley Town'!$E$12 | D9: ='Crawley Town'!$E$31 | E9: ='Crawley Town'!$E$32 | F9: =D9-E9
A10: 9 | B10: Gillingham | C10: ='Gillingham'!$E$14 | D10: ='Gillingham'!$E$33 | E10: ='Gillingham'!$E$34 | F10: =D10-E10
A11: 10 | B11: Port Vale | C11: ='Port Vale'!$E$12 | D11: ='Port Vale'!$E$31 | E11: ='Port Vale'!$E$32 | F11: =D11-E11
A12: 11 | B12: Walsall | C12: ='Walsall'!$E$13 | D12: ='Walsall'!$E$32 | E12: ='Walsall'!$E$33 | F12: =D12-E12
A13: 12 | B13: Barnet | C13: ='Barnet'!$E$12 | D13: ='Barnet'!$E$31 | E13: ='Barnet'!$E$32 | F13: =D13-E13
A14: 13 | B14: Crewe Alexandra | C14: ='Crewe Alexandra'!$E$14 | D14: ='Crewe Alexandra'!$E$33 | E14: ='Crewe Alexandra'!$E$34 | F14: =D14-E14
A15: 14 | B15: Grimsby Town | C15: ='Grimsby Town'!$E$14 | D15: ='Grimsby Town'!$E$33 | E15: ='Grimsby Town'!$E$34 | F15: =D15-E15
A16: 15 | B16: Oldham Athletic | C16: ='Oldham Athletic'!$E$13 | D16: ='Oldham Athletic'!$E$32 | E16: ='Oldham Athletic'!$E$33 | F16: =D16-E16
A17: 16 | B17: Tranmere Rovers | C17: ='Tranmere Rovers'!$E$14 | D17: ='Tranmere Rovers'!$E$33 | E17: ='Tranmere Rovers'!$E$34 | F17: =D17-E17
A18: 17 | B18: Bristol Rvs | C18: ='Bristol Rvs'!$E$14 | D18: ='Bristol Rvs'!$E$33 | E18: ='Bristol Rvs'!$E$34 | F18: =D18-E18
A19: 18 | B19: Cheltenham Town | C19: ='Cheltenham Town'!$E$14 | D19: ='Cheltenham Town'!$E$33 | E19: ='Cheltenham Town'!$E$34 | F19: =D19-E19
A20: 19 | B20: Swindon Town | C20: ='Swindon Town'!$E$14 | D20: ='Swindon Town'!$E$33 | E20: ='Swindon Town'!$E$34 | F20: =D20-E20
A21: 20 | B21: Colchester United | C21: ='Colchester United'!$E$13 | D21: ='Colchester United'!$E$32 | E21: ='Colchester United'!$E$33 | F21: =D21-E21
A22: 21 | B22: Salford City | C22: ='Salford City'!$E$14 | D22: ='Salford City'!$E$33 | E22: ='Salford City'!$E$34 | F22: =D22-E22
A23: 22 | B23: Northampton Town | C23: ='Northampton Town'!$E$12 | D23: ='Northampton Town'!$E$31 | E23: ='Northampton Town'!$E$32 | F23: =D23-E23
A24: 23 | B24: Fleetwood Town | C24: ='Fleetwood Town'!$E$14 | D24: ='Fleetwood Town'!$E$33 | E24: ='Fleetwood Town'!$E$34 | F24: =D24-E24
A25: 24 | B25: Rochdale | C25: ='Rochdale'!$E$14 | D25: ='Rochdale'!$E$33 | E25: ='Rochdale'!$E$34 | F25: =D25-E25

Sheet Dashboard
A1: League Dashboard
A2: Charts reference Overview / xPts Table live - re-run the pipeline and they update automatically.

Sheet Data Quality
A1: Data Quality Checker
A3: No issues found across 114 fixtures.

Sheet Match Log
A1: Date | B1: Home Team | C1: Away Team | D1: Home Goals | E1: Away Goals | F1: Home xG Pre-Match | G1: Away xG Pre-Match | H1: Home xG Actual | I1: Away xG Actual | J1: Home xG Delta | K1: Away xG Delta | L1: Supremacy Delta (Home) | M1: Total xG Delta | N1: Home xPts (Actual) | O1: Away xPts (Actual) | P1: Home xPts (Market) | Q1: Away xPts (Market)
A2: 2026-08-15 | B2: Accrington Stanley | C2: Colchester United | D2: 2 | E2: 2 | F2: 1.33 | G2: 1.19 | H2: 2.78 | I2: 0.74 | J2: 1.45 | K2: -0.45 | L2: 1.9 | M2: 1 | N2: 2.52 | O2: 0.35 | P2: 1.47 | Q2: 1.26
A3: 2026-08-15 | B3: York | C3: Bristol Rvs | D3: 3 | E3: 2 | F3: 1.41 | G3: 1.09 | H3: 1.93 | I3: 1.83 | J3: 0.52 | K3: 0.74 | L3: -0.22 | M3: 1.25 | N3: 1.45 | O3: 1.33 | P3: 1.59 | Q3: 1.14
A4: 2026-08-15 | B4: Crawley Town | C4: Crewe Alexandra | D4: 0 | E4: 1 | F4: 1.33 | G4: 1.29 | H4: 0.93 | I4: 2.2 | J4: -0.4 | K4: 0.91 | L4: -1.32 | M4: 0.51 | N4: 0.63 | O4: 2.18 | P4: 1.4 | Q4: 1.34
A5: 2026-08-15 | B5: Cheltenham Town | C5: Rotherham United | D5: 2 | E5: 1 | F5: 1.3 | G5: 1.36 | H5: 0.6 | I5: 2.2 | J5: -0.7 | K5: 0.84 | L5: -1.54 | M5: 0.14 | N5: 0.43 | O5: 2.4 | P5: 1.33 | Q5: 1.41
A6: 2026-08-15 | B6: Gillingham | C6: Walsall | D6: 0 | E6: 3 | F6: 1.43 | G6: 1.15 | H6: 1.45 | I6: 3.1 | J6: 0.02 | K6: 1.95 | L6: -1.94 | M6: 1.97 | N6: 0.59 | O6: 2.26 | P6: 1.57 | Q6: 1.17
A7: 2026-08-15 | B7: Chesterfield | C7: Fleetwood Town | D7: 0 | E7: 1 | F7: 1.63 | G7: 0.95 | H7: 2.17 | I7: 1.11 | J7: 0.54 | K7: 0.16 | L7: 0.38 | M7: 0.69 | N7: 2.04 | O7: 0.76 | P7: 1.85 | Q7: 0.91
A8: 2026-08-15 | B8: Newport County | C8: Rochdale | D8: 3 | E8: 0 | F8: 1.2 | G8: 1.39 | H8: 1.15 | I8: 0.16 | J8: -0.05 | K8: -1.23 | L8: 1.18 | M8: -1.28 | N8: 2.2 | O8: 0.47 | P8: 1.24 | Q8: 1.5
A9: 2026-08-15 | B9: Northampton Town | C9: Swindon Town | D9: 0 | E9: 0 | F9: 1.51 | G9: 1.14 | H9: 0.76 | I9: 0.2 | J9: -0.75 | K9: -0.94 | L9: 0.19 | M9: -1.7 | N9: 1.84 | O9: 0.72 | P9: 1.63 | Q9: 1.11
A10: 2026-08-15 | B10: Grimsby Town | C10: Exeter | D10: 1 | E10: 0 | F10: 1.7 | G10: 1.02 | H10: 1.43 | I10: 0.75 | J10: -0.27 | K10: -0.27 | L10: 0 | M10: -0.54 | N10: 1.87 | O10: 0.86 | P10: 1.84 | Q10: 0.92
A11: 2026-08-15 | B11: Tranmere Rovers | C11: Shrewsbury Town | D11: 2 | E11: 0 | F11: 1.4 | G11: 1.1 | H11: 1.16 | I11: 1.28 | J11: -0.24 | K11: 0.18 | L11: -0.42 | M11: -0.06 | N11: 1.28 | O11: 1.45 | P11: 1.58 | Q11: 1.15
A12: 2026-08-15 | B12: Barnet | C12: Salford City | D12: 3 | E12: 1 | F12: 1.42 | G12: 1.18 | H12: 1.62 | I12: 0.92 | J12: 0.2 | K12: -0.26 | L12: 0.46 | M12: -0.05 | N12: 1.86 | O12: 0.89 | P12: 1.54 | Q12: 1.2
A13: 2026-08-15 | B13: Oldham Athletic | C13: Port Vale | D13: 2 | E13: 0 | F13: 1.28 | G13: 1.23 | H13: 1.43 | I13: 0.51 | J13: 0.15 | K13: -0.72 | L13: 0.88 | M13: -0.57 | N13: 2.07 | O13: 0.66 | P13: 1.4 | Q13: 1.33
... A115: 2026-10-10 | B115: York | C115: Northampton Town | D115: 1 | E115: 1 | F115: 1.83 | G115: 0.95 | H115: 2.31 | I115: 0.98 | J115: 0.48 | K115: 0.03 | L115: 0.45 | M115: 0.51 | N115: 2.2 | O115: 0.62 | P115: 1.97 | Q115: 0.81

Sheet Home & Away Splits
A1: Supremacy Delta - Total / Home / Away
A2: Team | B2: Total Avg | C2: Total Median | D2: Home Avg | E2: Home Median | F2: Away Avg | G2: Away Median
A3: Chesterfield | B3: 0.59 | C3: 0.97 | D3: 0.79 | E3: 0.54 | F3: 0.39 | G3: 1.41
A4: Shrewsbury Town | B4: 0.54 | C4: 0.42 | D4: 0.26 | E4: 0.25 | F4: 0.82 | G4: 0.48
A5: Accrington Stanley | B5: 0.46 | C5: 0.39 | D5: 0.91 | E5: 0.94 | F5: 0.01 | G5: -0.04
A6: York | B6: 0.37 | C6: 0.63 | D6: 0.34 | E6: 0.45 | F6: 0.41 | G6: 0.93
A7: Exeter | B7: 0.35 | C7: 0.51 | D7: 0.81 | E7: 1.06 | F7: -0.1 | G7: 0
A8: Newport County | B8: 0.34 | C8: 0.49 | D8: 0.83 | E8: 1.03 | F8: -0.16 | G8: 0.36
A9: Rotherham United | B9: 0.31 | C9: 0.48 | D9: 0.14 | E9: -0.06 | F9: 0.48 | G9: 0.57
A10: Port Vale | B10: 0.2 | C10: 0.04 | D10: 0.88 | E10: 0.62 | F10: -0.49 | G10: -0.55
A11: Gillingham | B11: 0.16 | C11: 0.35 | D11: -0.05 | E11: 0.22 | F11: 0.38 | G11: 0.65
A12: Crawley Town | B12: 0.11 | C12: -0.33 | D12: -0.41 | E12: -0.72 | F12: 0.63 | G12: 1.06
A13: Bristol Rvs | B13: 0.01 | C13: -0.03 | D13: 0.73 | E13: 0.58 | F13: -0.71 | G13: -1.1
A14: Walsall | B14: 0.01 | C14: 0.22 | D14: 0.12 | E14: 0.32 | F14: -0.07 | G14: -0.43
... A26: Rochdale | B26: -0.74 | C26: -0.75 | D26: -1.18 | E26: -1.53 | F26: -0.3 | G26: -0.18
A28: Total Goals - Total / Home / Away
A29: Team | B29: Total GF | C29: Total GA | D29: Home GF | E29: Home GA | F29: Away GF | G29: Away GA
A30: Chesterfield | B30: 17 | C30: 14 | D30: 10 | E30: 7 | F30: 7 | G30: 7
A31: Shrewsbury Town | B31: 9 | C31: 15 | D31: 6 | E31: 6 | F31: 3 | G31: 9
A32: Accrington Stanley | B32: 13 | C32: 14 | D32: 9 | E32: 6 | F32: 4 | G32: 8
A33: York | B33: 17 | C33: 11 | D33: 13 | E33: 4 | F33: 4 | G33: 7
A34: Exeter | B34: 6 | C34: 6 | D34: 4 | E34: 1 | F34: 2 | G34: 5
A35: Newport County | B35: 13 | C35: 12 | D35: 9 | E35: 4 | F35: 4 | G35: 8
A36: Rotherham United | B36: 12 | C36: 16 | D36: 8 | E36: 10 | F36: 4 | G36: 6
A37: Port Vale | B37: 4 | C37: 9 | D37: 3 | E37: 1 | F37: 1 | G37: 8
A38: Gillingham | B38: 15 | C38: 10 | D38: 6 | E38: 4 | F38: 9 | G38: 6
A39: Crawley Town | B39: 8 | C39: 15 | D39: 3 | E39: 8 | F39: 5 | G39: 7
A40: Bristol Rvs | B40: 15 | C40: 17 | D40: 10 | E40: 6 | F40: 5 | G40: 11
A41: Walsall | B41: 12 | C41: 6 | D41: 5 | E41: 2 | F41: 7 | G41: 4
... A53: Rochdale | B53: 11 | C53: 12 | D53: 8 | E53: 6 | F53: 3 | G53: 6

Sheet Supremacy Delta
A1: Team | B1: Average | C1: MW1 | D1: MW2 | E1: MW3 | F1: MW4 | G1: MW5 | H1: MW6 | I1: MW7 | J1: MW8 | K1: MW9 | L1: MW10
A2: Chesterfield | B2: ='Chesterfield'!$E$25 | C2: ='Chesterfield'!$R$2 | D2: ='Chesterfield'!$R$3 | E2: ='Chesterfield'!$R$4 | F2: ='Chesterfield'!$R$5 | G2: ='Chesterfield'!$R$6 | H2: ='Chesterfield'!$R$7 | I2: ='Chesterfield'!$R$8 | J2: ='Chesterfield'!$R$9 | K2: ='Chesterfield'!$R$10 | L2: ='Chesterfield'!$R$11
A3: Shrewsbury Town | B3: ='Shrewsbury Town'!$E$25 | C3: ='Shrewsbury Town'!$R$2 | D3: ='Shrewsbury Town'!$R$3 | E3: ='Shrewsbury Town'!$R$4 | F3: ='Shrewsbury Town'!$R$5 | G3: ='Shrewsbury Town'!$R$6 | H3: ='Shrewsbury Town'!$R$7 | I3: ='Shrewsbury Town'!$R$8 | J3: ='Shrewsbury Town'!$R$9 | K3: ='Shrewsbury Town'!$R$10 | L3: ='Shrewsbury Town'!$R$11
A4: Accrington Stanley | B4: ='Accrington Stanley'!$E$25 | C4: ='Accrington Stanley'!$R$2 | D4: ='Accrington Stanley'!$R$3 | E4: ='Accrington Stanley'!$R$4 | F4: ='Accrington Stanley'!$R$5 | G4: ='Accrington Stanley'!$R$6 | H4: ='Accrington Stanley'!$R$7 | I4: ='Accrington Stanley'!$R$8 | J4: ='Accrington Stanley'!$R$9 | K4: ='Accrington Stanley'!$R$10 | L4: ='Accrington Stanley'!$R$11
A5: York | B5: ='York'!$E$24 | C5: ='York'!$R$2 | D5: ='York'!$R$3 | E5: ='York'!$R$4 | F5: ='York'!$R$5 | G5: ='York'!$R$6 | H5: ='York'!$R$7 | I5: ='York'!$R$8 | J5: ='York'!$R$9 | K5: ='York'!$R$10
A6: Exeter | B6: ='Exeter'!$E$25 | C6: ='Exeter'!$R$2 | D6: ='Exeter'!$R$3 | E6: ='Exeter'!$R$4 | F6: ='Exeter'!$R$5 | G6: ='Exeter'!$R$6 | H6: ='Exeter'!$R$7 | I6: ='Exeter'!$R$8 | J6: ='Exeter'!$R$9 | K6: ='Exeter'!$R$10 | L6: ='Exeter'!$R$11
A7: Newport County | B7: ='Newport County'!$E$25 | C7: ='Newport County'!$R$2 | D7: ='Newport County'!$R$3 | E7: ='Newport County'!$R$4 | F7: ='Newport County'!$R$5 | G7: ='Newport County'!$R$6 | H7: ='Newport County'!$R$7 | I7: ='Newport County'!$R$8 | J7: ='Newport County'!$R$9 | K7: ='Newport County'!$R$10 | L7: ='Newport County'!$R$11
A8: Rotherham United | B8: ='Rotherham United'!$E$25 | C8: ='Rotherham United'!$R$2 | D8: ='Rotherham United'!$R$3 | E8: ='Rotherham United'!$R$4 | F8: ='Rotherham United'!$R$5 | G8: ='Rotherham United'!$R$6 | H8: ='Rotherham United'!$R$7 | I8: ='Rotherham United'!$R$8 | J8: ='Rotherham United'!$R$9 | K8: ='Rotherham United'!$R$10 | L8: ='Rotherham United'!$R$11
A9: Port Vale | B9: ='Port Vale'!$E$23 | C9: ='Port Vale'!$R$2 | D9: ='Port Vale'!$R$3 | E9: ='Port Vale'!$R$4 | F9: ='Port Vale'!$R$5 | G9: ='Port Vale'!$R$6 | H9: ='Port Vale'!$R$7 | I9: ='Port Vale'!$R$8 | J9: ='Port Vale'!$R$9
A10: Gillingham | B10: ='Gillingham'!$E$25 | C10: ='Gillingham'!$R$2 | D10: ='Gillingham'!$R$3 | E10: ='Gillingham'!$R$4 | F10: ='Gillingham'!$R$5 | G10: ='Gillingham'!$R$6 | H10: ='Gillingham'!$R$7 | I10: ='Gillingham'!$R$8 | J10: ='Gillingham'!$R$9 | K10: ='Gillingham'!$R$10 | L10: ='Gillingham'!$R$11
A11: Crawley Town | B11: ='Crawley Town'!$E$23 | C11: ='Crawley Town'!$R$2 | D11: ='Crawley Town'!$R$3 | E11: ='Crawley Town'!$R$4 | F11: ='Crawley Town'!$R$5 | G11: ='Crawley Town'!$R$6 | H11: ='Crawley Town'!$R$7 | I11: ='Crawley Town'!$R$8 | J11: ='Crawley Town'!$R$9
A12: Bristol Rvs | B12: ='Bristol Rvs'!$E$25 | C12: ='Bristol Rvs'!$R$2 | D12: ='Bristol Rvs'!$R$3 | E12: ='Bristol Rvs'!$R$4 | F12: ='Bristol Rvs'!$R$5 | G12: ='Bristol Rvs'!$R$6 | H12: ='Bristol Rvs'!$R$7 | I12: ='Bristol Rvs'!$R$8 | J12: ='Bristol Rvs'!$R$9 | K12: ='Bristol Rvs'!$R$10 | L12: ='Bristol Rvs'!$R$11
A13: Walsall | B13: ='Walsall'!$E$24 | C13: ='Walsall'!$R$2 | D13: ='Walsall'!$R$3 | E13: ='Walsall'!$R$4 | F13: ='Walsall'!$R$5 | G13: ='Walsall'!$R$6 | H13: ='Walsall'!$R$7 | I13: ='Walsall'!$R$8 | J13: ='Walsall'!$R$9 | K13: ='Walsall'!$R$10
A14: Grimsby Town | B14: ='Grimsby Town'!$E$25 | C14: ='Grimsby Town'!$R$2 | D14: ='Grimsby Town'!$R$3 | E14: ='Grimsby Town'!$R$4 | F14: ='Grimsby Town'!$R$5 | G14: ='Grimsby Town'!$R$6 | H14: ='Grimsby Town'!$R$7 | I14: ='Grimsby Town'!$R$8 | J14: ='Grimsby Town'!$R$9 | K14: ='Grimsby Town'!$R$10 | L14: ='Grimsby Town'!$R$11
A15: Barnet | B15: ='Barnet'!$E$23 | C15: ='Barnet'!$R$2 | D15: ='Barnet'!$R$3 | E15: ='Barnet'!$R$4 | F15: ='Barnet'!$R$5 | G15: ='Barnet'!$R$6 | H15: ='Barnet'!$R$7 | I15: ='Barnet'!$R$8 | J15: ='Barnet'!$R$9
A16: Oldham Athletic | B16: ='Oldham Athletic'!$E$24 | C16: ='Oldham Athletic'!$R$2 | D16: ='Oldham Athletic'!$R$3 | E16: ='Oldham Athletic'!$R$4 | F16: ='Oldham Athletic'!$R$5 | G16: ='Oldham Athletic'!$R$6 | H16: ='Oldham Athletic'!$R$7 | I16: ='Oldham Athletic'!$R$8 | J16: ='Oldham Athletic'!$R$9 | K16: ='Oldham Athletic'!$R$10
A17: Crewe Alexandra | B17: ='Crewe Alexandra'!$E$25 | C17: ='Crewe Alexandra'!$R$2 | D17: ='Crewe Alexandra'!$R$3 | E17: ='Crewe Alexandra'!$R$4 | F17: ='Crewe Alexandra'!$R$5 | G17: ='Crewe Alexandra'!$R$6 | H17: ='Crewe Alexandra'!$R$7 | I17: ='Crewe Alexandra'!$R$8 | J17: ='Crewe Alexandra'!$R$9 | K17: ='Crewe Alexandra'!$R$10 | L17: ='Crewe Alexandra'!$R$11
A18: Tranmere Rovers | B18: ='Tranmere Rovers'!$E$25 | C18: ='Tranmere Rovers'!$R$2 | D18: ='Tranmere Rovers'!$R$3 | E18: ='Tranmere Rovers'!$R$4 | F18: ='Tranmere Rovers'!$R$5 | G18: ='Tranmere Rovers'!$R$6 | H18: ='Tranmere Rovers'!$R$7 | I18: ='Tranmere Rovers'!$R$8 | J18: ='Tranmere Rovers'!$R$9 | K18: ='Tranmere Rovers'!$R$10 | L18: ='Tranmere Rovers'!$R$11
A19: Swindon Town | B19: ='Swindon Town'!$E$25 | C19: ='Swindon Town'!$R$2 | D19: ='Swindon Town'!$R$3 | E19: ='Swindon Town'!$R$4 | F19: ='Swindon Town'!$R$5 | G19: ='Swindon Town'!$R$6 | H19: ='Swindon Town'!$R$7 | I19: ='Swindon Town'!$R$8 | J19: ='Swindon Town'!$R$9 | K19: ='Swindon Town'!$R$10 | L19: ='Swindon Town'!$R$11
A20: Cheltenham Town | B20: ='Cheltenham Town'!$E$25 | C20: ='Cheltenham Town'!$R$2 | D20: ='Cheltenham Town'!$R$3 | E20: ='Cheltenham Town'!$R$4 | F20: ='Cheltenham Town'!$R$5 | G20: ='Cheltenham Town'!$R$6 | H20: ='Cheltenham Town'!$R$7 | I20: ='Cheltenham Town'!$R$8 | J20: ='Cheltenham Town'!$R$9 | K20: ='Cheltenham Town'!$R$10 | L20: ='Cheltenham Town'!$R$11
A21: Salford City | B21: ='Salford City'!$E$25 | C21: ='Salford City'!$R$2 | D21: ='Salford City'!$R$3 | E21: ='Salford City'!$R$4 | F21: ='Salford City'!$R$5 | G21: ='Salford City'!$R$6 | H21: ='Salford City'!$R$7 | I21: ='Salford City'!$R$8 | J21: ='Salford City'!$R$9 | K21: ='Salford City'!$R$10 | L21: ='Salford City'!$R$11
A22: Colchester United | B22: ='Colchester United'!$E$24 | C22: ='Colchester United'!$R$2 | D22: ='Colchester United'!$R$3 | E22: ='Colchester United'!$R$4 | F22: ='Colchester United'!$R$5 | G22: ='Colchester United'!$R$6 | H22: ='Colchester United'!$R$7 | I22: ='Colchester United'!$R$8 | J22: ='Colchester United'!$R$9 | K22: ='Colchester United'!$R$10
A23: Northampton Town | B23: ='Northampton Town'!$E$23 | C23: ='Northampton Town'!$R$2 | D23: ='Northampton Town'!$R$3 | E23: ='Northampton Town'!$R$4 | F23: ='Northampton Town'!$R$5 | G23: ='Northampton Town'!$R$6 | H23: ='Northampton Town'!$R$7 | I23: ='Northampton Town'!$R$8 | J23: ='Northampton Town'!$R$9
A24: Fleetwood Town | B24: ='Fleetwood Town'!$E$25 | C24: ='Fleetwood Town'!$R$2 | D24: ='Fleetwood Town'!$R$3 | E24: ='Fleetwood Town'!$R$4 | F24: ='Fleetwood Town'!$R$5 | G24: ='Fleetwood Town'!$R$6 | H24: ='Fleetwood Town'!$R$7 | I24: ='Fleetwood Town'!$R$8 | J24: ='Fleetwood Town'!$R$9 | K24: ='Fleetwood Town'!$R$10 | L24: ='Fleetwood Town'!$R$11
A25: Rochdale | B25: ='Rochdale'!$E$25 | C25: ='Rochdale'!$R$2 | D25: ='Rochdale'!$R$3 | E25: ='Rochdale'!$R$4 | F25: ='Rochdale'!$R$5 | G25: ='Rochdale'!$R$6 | H25: ='Rochdale'!$R$7 | I25: ='Rochdale'!$R$8 | J25: ='Rochdale'!$R$9 | K25: ='Rochdale'!$R$10 | L25: ='Rochdale'!$R$11

Sheet Supremacy Delta (Home)
A1: Team | B1: Average | C1: H1 | D1: H2 | E1: H3 | F1: H4 | G1: H5
A2: Accrington Stanley | B2: 0.91 | C2: 1.9 | D2: 0.94 | E2: 0.09 | F2: -0.36 | G2: 2
A3: Port Vale | B3: 0.88 | C3: 0.31 | D3: -0.43 | E3: 0.93 | F3: 2.71
A4: Newport County | B4: 0.83 | C4: 1.18 | D4: 0.08 | E4: 1.97 | F4: -0.09 | G4: 1.03
A5: Exeter | B5: 0.81 | C5: 1.11 | D5: 0.61 | E5: 1.06 | F5: -0.44 | G5: 1.7
A6: Chesterfield | B6: 0.79 | C6: 0.38 | D6: 0.54 | E6: -0.34 | F6: 1.62 | G6: 1.73
A7: Grimsby Town | B7: 0.77 | C7: 0 | D7: 0.68 | E7: 1.15 | F7: 2.44 | G7: -0.43
A8: Bristol Rvs | B8: 0.73 | C8: 2.44 | D8: 1.48 | E8: -0.57 | F8: 0.58 | G8: -0.29
A9: York | B9: 0.34 | C9: -0.22 | D9: -0.56 | E9: 1.15 | F9: 0.86 | G9: 0.45
A10: Colchester United | B10: 0.29 | C10: 2.02 | D10: 0.1 | E10: 0.28 | F10: -1.23
A11: Shrewsbury Town | B11: 0.26 | C11: 1.29 | D11: 0.25 | E11: 0.34 | F11: -0.14 | G11: -0.46
A12: Barnet | B12: 0.2 | C12: 0.46 | D12: -0.57 | E12: 0.74 | F12: 0.16
A13: Rotherham United | B13: 0.14 | C13: -1.39 | D13: 2.07 | E13: 1.16 | F13: -0.06 | G13: -1.1
A14: Swindon Town | B14: 0.13 | C14: -0.76 | D14: 1.82 | E14: 0.51 | F14: 0.04 | G14: -0.94
A15: Walsall | B15: 0.12 | C15: 0.41 | D15: -0.68 | E15: 0.53 | F15: 0.22
A16: Tranmere Rovers | B16: -0.03 | C16: -0.42 | D16: -1.58 | E16: 0.28 | F16: 1.39 | G16: 0.18
A17: Gillingham | B17: -0.05 | C17: -1.94 | D17: 0.48 | E17: 0.22 | F17: 2.38 | G17: -1.4
A18: Oldham Athletic | B18: -0.07 | C18: 0.88 | D18: 2.16 | E18: -1.49 | F18: -0.64 | G18: -1.27
A19: Fleetwood Town | B19: -0.36 | C19: -0.65 | D19: -0.59 | E19: -0.48 | F19: -0.49 | G19: 0.43
A20: Crawley Town | B20: -0.41 | C20: -1.32 | D20: -0.88 | E20: -0.57 | F20: 1.11
A21: Salford City | B21: -0.56 | C21: -2.23 | D21: 0.73 | E21: -0.98 | F21: -0.9 | G21: 0.57
A22: Crewe Alexandra | B22: -0.63 | C22: -0.62 | D22: -0.58 | E22: -1.22 | F22: -1.82 | G22: 1.1
A23: Cheltenham Town | B23: -0.72 | C23: -1.54 | D23: -0.63 | E23: 0.21 | F23: -1.41 | G23: -0.22
A24: Northampton Town | B24: -0.92 | C24: 0.19 | D24: -2.84 | E24: -0.62 | F24: -0.4
A25: Rochdale | B25: -1.18 | C25: -2.2 | D25: -0.97 | E25: -1.53 | F25: -1.53 | G25: 0.35

Sheet Supremacy Delta (Away)
A1: Team | B1: Average | C1: A1 | D1: A2 | E1: A3 | F1: A4 | G1: A5
A2: Shrewsbury Town | B2: 0.82 | C2: 0.42 | D2: 0.97 | E2: 0.48 | F2: 1.82 | G2: 0.43
A3: Crawley Town | B3: 0.63 | C3: 2.2 | D3: 2.84 | E3: -0.09 | F3: -2.44
A4: Crewe Alexandra | B4: 0.49 | C4: 1.32 | D4: 0.43 | E4: -0.28 | F4: 0.06 | G4: 0.94
A5: Rotherham United | B5: 0.48 | C5: 1.54 | D5: 1.58 | E5: 0.57 | F5: 0.4 | G5: -1.7
A6: York | B6: 0.4 | C6: 1.39 | D6: 0.63 | E6: 1.22 | F6: -1.62
A7: Chesterfield | B7: 0.39 | C7: 2.23 | D7: -2.07 | E7: 1.49 | F7: 1.41 | G7: -1.11
A8: Gillingham | B8: 0.38 | C8: 0.65 | D8: -0.54 | E8: 1.53 | F8: -0.86 | G8: 1.1
A9: Cheltenham Town | B9: 0.23 | C9: 0.76 | D9: 0.57 | E9: 0.57 | F9: 1.23 | G9: -2
A10: Accrington Stanley | B10: 0.01 | C10: -1.11 | D10: 0.68 | E10: -0.74 | F10: -0.04 | G10: 1.27
A11: Oldham Athletic | B11: -0.05 | C11: -2.02 | D11: 0.59 | E11: -0.28 | F11: 1.53
A12: Walsall | B12: -0.07 | C12: 1.94 | D12: 0.58 | E12: -1.06 | F12: -1.39 | G12: -0.43
A13: Exeter | B13: -0.1 | C13: 0 | D13: 0.56 | E13: -0.93 | F13: -0.58 | G13: 0.46
A14: Newport County | B14: -0.16 | C14: -2.44 | D14: -0.73 | E14: 0.62 | F14: 0.36 | G14: 1.4
A15: Northampton Town | B15: -0.16 | C15: 0.62 | D15: -0.48 | E15: -0.34 | F15: -0.45
A16: Salford City | B16: -0.2 | C16: -0.46 | D16: -0.25 | E16: -1.16 | F16: 0.64 | G16: 0.22
A17: Rochdale | B17: -0.3 | C17: -1.18 | D17: -0.1 | E17: -0.53 | F17: 0.49 | G17: -0.18
A18: Barnet | B18: -0.32 | C18: -1.29 | D18: -0.61 | E18: 0.34 | F18: 0.29
A19: Tranmere Rovers | B19: -0.38 | C19: -0.31 | D19: -0.08 | E19: -0.22 | F19: 0.44 | G19: -1.73
A20: Port Vale | B20: -0.49 | C20: -0.88 | D20: -1.82 | E20: 0.98 | F20: -0.22
A21: Swindon Town | B21: -0.59 | C21: -0.19 | D21: -2.16 | E21: -1.15 | F21: 0.9 | G21: -0.35
A22: Bristol Rvs | B22: -0.71 | C22: 0.22 | D22: 0.88 | E22: -1.15 | F22: -2.38 | G22: -1.1
A23: Fleetwood Town | B23: -0.75 | C23: -0.38 | D23: -0.68 | E23: -1.97 | F23: -0.16 | G23: -0.57
A24: Grimsby Town | B24: -0.84 | C24: -0.41 | D24: -0.94 | E24: -0.21 | F24: 0.09 | G24: -2.71
A25: Colchester United | B25: -0.96 | C25: -1.9 | D25: -1.48 | E25: -0.51 | F25: 0.14 | G25: -1.03

Sheet Total xG Delta
A1: Team | B1: Average | C1: MW1 | D1: MW2 | E1: MW3 | F1: MW4 | G1: MW5 | H1: MW6 | I1: MW7 | J1: MW8 | K1: MW9 | L1: MW10 | M1: Median
A2: Barnet | B2: ='Barnet'!$E$25 | C2: ='Barnet'!$S$2 | D2: ='Barnet'!$S$3 | E2: ='Barnet'!$S$4 | F2: ='Barnet'!$S$5 | G2: ='Barnet'!$S$6 | H2: ='Barnet'!$S$7 | I2: ='Barnet'!$S$8 | J2: ='Barnet'!$S$9 | M2: ='Barnet'!$E$26
A3: Chesterfield | B3: ='Chesterfield'!$E$27 | C3: ='Chesterfield'!$S$2 | D3: ='Chesterfield'!$S$3 | E3: ='Chesterfield'!$S$4 | F3: ='Chesterfield'!$S$5 | G3: ='Chesterfield'!$S$6 | H3: ='Chesterfield'!$S$7 | I3: ='Chesterfield'!$S$8 | J3: ='Chesterfield'!$S$9 | K3: ='Chesterfield'!$S$10 | L3: ='Chesterfield'!$S$11 | M3: ='Chesterfield'!$E$28
A4: Crawley Town | B4: ='Crawley Town'!$E$25 | C4: ='Crawley Town'!$S$2 | D4: ='Crawley Town'!$S$3 | E4: ='Crawley Town'!$S$4 | F4: ='Crawley Town'!$S$5 | G4: ='Crawley Town'!$S$6 | H4: ='Crawley Town'!$S$7 | I4: ='Crawley Town'!$S$8 | J4: ='Crawley Town'!$S$9 | M4: ='Crawley Town'!$E$26
A5: Grimsby Town | B5: ='Grimsby Town'!$E$27 | C5: ='Grimsby Town'!$S$2 | D5: ='Grimsby Town'!$S$3 | E5: ='Grimsby Town'!$S$4 | F5: ='Grimsby Town'!$S$5 | G5: ='Grimsby Town'!$S$6 | H5: ='Grimsby Town'!$S$7 | I5: ='Grimsby Town'!$S$8 | J5: ='Grimsby Town'!$S$9 | K5: ='Grimsby Town'!$S$10 | L5: ='Grimsby Town'!$S$11 | M5: ='Grimsby Town'!$E$28
A6: Accrington Stanley | B6: ='Accrington Stanley'!$E$27 | C6: ='Accrington Stanley'!$S$2 | D6: ='Accrington Stanley'!$S$3 | E6: ='Accrington Stanley'!$S$4 | F6: ='Accrington Stanley'!$S$5 | G6: ='Accrington Stanley'!$S$6 | H6: ='Accrington Stanley'!$S$7 | I6: ='Accrington Stanley'!$S$8 | J6: ='Accrington Stanley'!$S$9 | K6: ='Accrington Stanley'!$S$10 | L6: ='Accrington Stanley'!$S$11 | M6: ='Accrington Stanley'!$E$28
A7: York | B7: ='York'!$E$26 | C7: ='York'!$S$2 | D7: ='York'!$S$3 | E7: ='York'!$S$4 | F7: ='York'!$S$5 | G7: ='York'!$S$6 | H7: ='York'!$S$7 | I7: ='York'!$S$8 | J7: ='York'!$S$9 | K7: ='York'!$S$10 | M7: ='York'!$E$27
A8: Fleetwood Town | B8: ='Fleetwood Town'!$E$27 | C8: ='Fleetwood Town'!$S$2 | D8: ='Fleetwood Town'!$S$3 | E8: ='Fleetwood Town'!$S$4 | F8: ='Fleetwood Town'!$S$5 | G8: ='Fleetwood Town'!$S$6 | H8: ='Fleetwood Town'!$S$7 | I8: ='Fleetwood Town'!$S$8 | J8: ='Fleetwood Town'!$S$9 | K8: ='Fleetwood Town'!$S$10 | L8: ='Fleetwood Town'!$S$11 | M8: ='Fleetwood Town'!$E$28
A9: Bristol Rvs | B9: ='Bristol Rvs'!$E$27 | C9: ='Bristol Rvs'!$S$2 | D9: ='Bristol Rvs'!$S$3 | E9: ='Bristol Rvs'!$S$4 | F9: ='Bristol Rvs'!$S$5 | G9: ='Bristol Rvs'!$S$6 | H9: ='Bristol Rvs'!$S$7 | I9: ='Bristol Rvs'!$S$8 | J9: ='Bristol Rvs'!$S$9 | K9: ='Bristol Rvs'!$S$10 | L9: ='Bristol Rvs'!$S$11 | M9: ='Bristol Rvs'!$E$28
A10: Walsall | B10: ='Walsall'!$E$26 | C10: ='Walsall'!$S$2 | D10: ='Walsall'!$S$3 | E10: ='Walsall'!$S$4 | F10: ='Walsall'!$S$5 | G10: ='Walsall'!$S$6 | H10: ='Walsall'!$S$7 | I10: ='Walsall'!$S$8 | J10: ='Walsall'!$S$9 | K10: ='Walsall'!$S$10 | M10: ='Walsall'!$E$27
A11: Tranmere Rovers | B11: ='Tranmere Rovers'!$E$27 | C11: ='Tranmere Rovers'!$S$2 | D11: ='Tranmere Rovers'!$S$3 | E11: ='Tranmere Rovers'!$S$4 | F11: ='Tranmere Rovers'!$S$5 | G11: ='Tranmere Rovers'!$S$6 | H11: ='Tranmere Rovers'!$S$7 | I11: ='Tranmere Rovers'!$S$8 | J11: ='Tranmere Rovers'!$S$9 | K11: ='Tranmere Rovers'!$S$10 | L11: ='Tranmere Rovers'!$S$11 | M11: ='Tranmere Rovers'!$E$28
A12: Cheltenham Town | B12: ='Cheltenham Town'!$E$27 | C12: ='Cheltenham Town'!$S$2 | D12: ='Cheltenham Town'!$S$3 | E12: ='Cheltenham Town'!$S$4 | F12: ='Cheltenham Town'!$S$5 | G12: ='Cheltenham Town'!$S$6 | H12: ='Cheltenham Town'!$S$7 | I12: ='Cheltenham Town'!$S$8 | J12: ='Cheltenham Town'!$S$9 | K12: ='Cheltenham Town'!$S$10 | L12: ='Cheltenham Town'!$S$11 | M12: ='Cheltenham Town'!$E$28
A13: Colchester United | B13: ='Colchester United'!$E$26 | C13: ='Colchester United'!$S$2 | D13: ='Colchester United'!$S$3 | E13: ='Colchester United'!$S$4 | F13: ='Colchester United'!$S$5 | G13: ='Colchester United'!$S$6 | H13: ='Colchester United'!$S$7 | I13: ='Colchester United'!$S$8 | J13: ='Colchester United'!$S$9 | K13: ='Colchester United'!$S$10 | M13: ='Colchester United'!$E$27
A14: Rotherham United | B14: ='Rotherham United'!$E$27 | C14: ='Rotherham United'!$S$2 | D14: ='Rotherham United'!$S$3 | E14: ='Rotherham United'!$S$4 | F14: ='Rotherham United'!$S$5 | G14: ='Rotherham United'!$S$6 | H14: ='Rotherham United'!$S$7 | I14: ='Rotherham United'!$S$8 | J14: ='Rotherham United'!$S$9 | K14: ='Rotherham United'!$S$10 | L14: ='Rotherham United'!$S$11 | M14: ='Rotherham United'!$E$28
A15: Gillingham | B15: ='Gillingham'!$E$27 | C15: ='Gillingham'!$S$2 | D15: ='Gillingham'!$S$3 | E15: ='Gillingham'!$S$4 | F15: ='Gillingham'!$S$5 | G15: ='Gillingham'!$S$6 | H15: ='Gillingham'!$S$7 | I15: ='Gillingham'!$S$8 | J15: ='Gillingham'!$S$9 | K15: ='Gillingham'!$S$10 | L15: ='Gillingham'!$S$11 | M15: ='Gillingham'!$E$28
A16: Oldham Athletic | B16: ='Oldham Athletic'!$E$26 | C16: ='Oldham Athletic'!$S$2 | D16: ='Oldham Athletic'!$S$3 | E16: ='Oldham Athletic'!$S$4 | F16: ='Oldham Athletic'!$S$5 | G16: ='Oldham Athletic'!$S$6 | H16: ='Oldham Athletic'!$S$7 | I16: ='Oldham Athletic'!$S$8 | J16: ='Oldham Athletic'!$S$9 | K16: ='Oldham Athletic'!$S$10 | M16: ='Oldham Athletic'!$E$27
A17: Swindon Town | B17: ='Swindon Town'!$E$27 | C17: ='Swindon Town'!$S$2 | D17: ='Swindon Town'!$S$3 | E17: ='Swindon Town'!$S$4 | F17: ='Swindon Town'!$S$5 | G17: ='Swindon Town'!$S$6 | H17: ='Swindon Town'!$S$7 | I17: ='Swindon Town'!$S$8 | J17: ='Swindon Town'!$S$9 | K17: ='Swindon Town'!$S$10 | L17: ='Swindon Town'!$S$11 | M17: ='Swindon Town'!$E$28
A18: Shrewsbury Town | B18: ='Shrewsbury Town'!$E$27 | C18: ='Shrewsbury Town'!$S$2 | D18: ='Shrewsbury Town'!$S$3 | E18: ='Shrewsbury Town'!$S$4 | F18: ='Shrewsbury Town'!$S$5 | G18: ='Shrewsbury Town'!$S$6 | H18: ='Shrewsbury Town'!$S$7 | I18: ='Shrewsbury Town'!$S$8 | J18: ='Shrewsbury Town'!$S$9 | K18: ='Shrewsbury Town'!$S$10 | L18: ='Shrewsbury Town'!$S$11 | M18: ='Shrewsbury Town'!$E$28
A19: Rochdale | B19: ='Rochdale'!$E$27 | C19: ='Rochdale'!$S$2 | D19: ='Rochdale'!$S$3 | E19: ='Rochdale'!$S$4 | F19: ='Rochdale'!$S$5 | G19: ='Rochdale'!$S$6 | H19: ='Rochdale'!$S$7 | I19: ='Rochdale'!$S$8 | J19: ='Rochdale'!$S$9 | K19: ='Rochdale'!$S$10 | L19: ='Rochdale'!$S$11 | M19: ='Rochdale'!$E$28
A20: Port Vale | B20: ='Port Vale'!$E$25 | C20: ='Port Vale'!$S$2 | D20: ='Port Vale'!$S$3 | E20: ='Port Vale'!$S$4 | F20: ='Port Vale'!$S$5 | G20: ='Port Vale'!$S$6 | H20: ='Port Vale'!$S$7 | I20: ='Port Vale'!$S$8 | J20: ='Port Vale'!$S$9 | M20: ='Port Vale'!$E$26
A21: Crewe Alexandra | B21: ='Crewe Alexandra'!$E$27 | C21: ='Crewe Alexandra'!$S$2 | D21: ='Crewe Alexandra'!$S$3 | E21: ='Crewe Alexandra'!$S$4 | F21: ='Crewe Alexandra'!$S$5 | G21: ='Crewe Alexandra'!$S$6 | H21: ='Crewe Alexandra'!$S$7 | I21: ='Crewe Alexandra'!$S$8 | J21: ='Crewe Alexandra'!$S$9 | K21: ='Crewe Alexandra'!$S$10 | L21: ='Crewe Alexandra'!$S$11 | M21: ='Crewe Alexandra'!$E$28
A22: Exeter | B22: ='Exeter'!$E$27 | C22: ='Exeter'!$S$2 | D22: ='Exeter'!$S$3 | E22: ='Exeter'!$S$4 | F22: ='Exeter'!$S$5 | G22: ='Exeter'!$S$6 | H22: ='Exeter'!$S$7 | I22: ='Exeter'!$S$8 | J22: ='Exeter'!$S$9 | K22: ='Exeter'!$S$10 | L22: ='Exeter'!$S$11 | M22: ='Exeter'!$E$28
A23: Newport County | B23: ='Newport County'!$E$27 | C23: ='Newport County'!$S$2 | D23: ='Newport County'!$S$3 | E23: ='Newport County'!$S$4 | F23: ='Newport County'!$S$5 | G23: ='Newport County'!$S$6 | H23: ='Newport County'!$S$7 | I23: ='Newport County'!$S$8 | J23: ='Newport County'!$S$9 | K23: ='Newport County'!$S$10 | L23: ='Newport County'!$S$11 | M23: ='Newport County'!$E$28
A24: Salford City | B24: ='Salford City'!$E$27 | C24: ='Salford City'!$S$2 | D24: ='Salford City'!$S$3 | E24: ='Salford City'!$S$4 | F24: ='Salford City'!$S$5 | G24: ='Salford City'!$S$6 | H24: ='Salford City'!$S$7 | I24: ='Salford City'!$S$8 | J24: ='Salford City'!$S$9 | K24: ='Salford City'!$S$10 | L24: ='Salford City'!$S$11 | M24: ='Salford City'!$E$28
A25: Northampton Town | B25: ='Northampton Town'!$E$25 | C25: ='Northampton Town'!$S$2 | D25: ='Northampton Town'!$S$3 | E25: ='Northampton Town'!$S$4 | F25: ='Northampton Town'!$S$5 | G25: ='Northampton Town'!$S$6 | H25: ='Northampton Town'!$S$7 | I25: ='Northampton Town'!$S$8 | J25: ='Northampton Town'!$S$9 | M25: ='Northampton Town'!$E$26

Sheet xPts Delta
A1: Team | B1: Average | C1: MW1 | D1: MW2 | E1: MW3 | F1: MW4 | G1: MW5 | H1: MW6 | I1: MW7 | J1: MW8 | K1: MW9 | L1: MW10
A2: Chesterfield | B2: ='Chesterfield'!$E$35 | C2: ='Chesterfield'!$V$2 | D2: ='Chesterfield'!$V$3 | E2: ='Chesterfield'!$V$4 | F2: ='Chesterfield'!$V$5 | G2: ='Chesterfield'!$V$6 | H2: ='Chesterfield'!$V$7 | I2: ='Chesterfield'!$V$8 | J2: ='Chesterfield'!$V$9 | K2: ='Chesterfield'!$V$10 | L2: ='Chesterfield'!$V$11
A3: Shrewsbury Town | B3: ='Shrewsbury Town'!$E$35 | C3: ='Shrewsbury Town'!$V$2 | D3: ='Shrewsbury Town'!$V$3 | E3: ='Shrewsbury Town'!$V$4 | F3: ='Shrewsbury Town'!$V$5 | G3: ='Shrewsbury Town'!$V$6 | H3: ='Shrewsbury Town'!$V$7 | I3: ='Shrewsbury Town'!$V$8 | J3: ='Shrewsbury Town'!$V$9 | K3: ='Shrewsbury Town'!$V$10 | L3: ='Shrewsbury Town'!$V$11
A4: Newport County | B4: ='Newport County'!$E$35 | C4: ='Newport County'!$V$2 | D4: ='Newport County'!$V$3 | E4: ='Newport County'!$V$4 | F4: ='Newport County'!$V$5 | G4: ='Newport County'!$V$6 | H4: ='Newport County'!$V$7 | I4: ='Newport County'!$V$8 | J4: ='Newport County'!$V$9 | K4: ='Newport County'!$V$10 | L4: ='Newport County'!$V$11
A5: Accrington Stanley | B5: ='Accrington Stanley'!$E$35 | C5: ='Accrington Stanley'!$V$2 | D5: ='Accrington Stanley'!$V$3 | E5: ='Accrington Stanley'!$V$4 | F5: ='Accrington Stanley'!$V$5 | G5: ='Accrington Stanley'!$V$6 | H5: ='Accrington Stanley'!$V$7 | I5: ='Accrington Stanley'!$V$8 | J5: ='Accrington Stanley'!$V$9 | K5: ='Accrington Stanley'!$V$10 | L5: ='Accrington Stanley'!$V$11
A6: Exeter | B6: ='Exeter'!$E$35 | C6: ='Exeter'!$V$2 | D6: ='Exeter'!$V$3 | E6: ='Exeter'!$V$4 | F6: ='Exeter'!$V$5 | G6: ='Exeter'!$V$6 | H6: ='Exeter'!$V$7 | I6: ='Exeter'!$V$8 | J6: ='Exeter'!$V$9 | K6: ='Exeter'!$V$10 | L6: ='Exeter'!$V$11
A7: Crawley Town | B7: ='Crawley Town'!$E$33 | C7: ='Crawley Town'!$V$2 | D7: ='Crawley Town'!$V$3 | E7: ='Crawley Town'!$V$4 | F7: ='Crawley Town'!$V$5 | G7: ='Crawley Town'!$V$6 | H7: ='Crawley Town'!$V$7 | I7: ='Crawley Town'!$V$8 | J7: ='Crawley Town'!$V$9
A8: York | B8: ='York'!$E$34 | C8: ='York'!$V$2 | D8: ='York'!$V$3 | E8: ='York'!$V$4 | F8: ='York'!$V$5 | G8: ='York'!$V$6 | H8: ='York'!$V$7 | I8: ='York'!$V$8 | J8: ='York'!$V$9 | K8: ='York'!$V$10
A9: Rotherham United | B9: ='Rotherham United'!$E$35 | C9: ='Rotherham United'!$V$2 | D9: ='Rotherham United'!$V$3 | E9: ='Rotherham United'!$V$4 | F9: ='Rotherham United'!$V$5 | G9: ='Rotherham United'!$V$6 | H9: ='Rotherham United'!$V$7 | I9: ='Rotherham United'!$V$8 | J9: ='Rotherham United'!$V$9 | K9: ='Rotherham United'!$V$10 | L9: ='Rotherham United'!$V$11
A10: Gillingham | B10: ='Gillingham'!$E$35 | C10: ='Gillingham'!$V$2 | D10: ='Gillingham'!$V$3 | E10: ='Gillingham'!$V$4 | F10: ='Gillingham'!$V$5 | G10: ='Gillingham'!$V$6 | H10: ='Gillingham'!$V$7 | I10: ='Gillingham'!$V$8 | J10: ='Gillingham'!$V$9 | K10: ='Gillingham'!$V$10 | L10: ='Gillingham'!$V$11
A11: Port Vale | B11: ='Port Vale'!$E$33 | C11: ='Port Vale'!$V$2 | D11: ='Port Vale'!$V$3 | E11: ='Port Vale'!$V$4 | F11: ='Port Vale'!$V$5 | G11: ='Port Vale'!$V$6 | H11: ='Port Vale'!$V$7 | I11: ='Port Vale'!$V$8 | J11: ='Port Vale'!$V$9
A12: Walsall | B12: ='Walsall'!$E$34 | C12: ='Walsall'!$V$2 | D12: ='Walsall'!$V$3 | E12: ='Walsall'!$V$4 | F12: ='Walsall'!$V$5 | G12: ='Walsall'!$V$6 | H12: ='Walsall'!$V$7 | I12: ='Walsall'!$V$8 | J12: ='Walsall'!$V$9 | K12: ='Walsall'!$V$10
A13: Crewe Alexandra | B13: ='Crewe Alexandra'!$E$35 | C13: ='Crewe Alexandra'!$V$2 | D13: ='Crewe Alexandra'!$V$3 | E13: ='Crewe Alexandra'!$V$4 | F13: ='Crewe Alexandra'!$V$5 | G13: ='Crewe Alexandra'!$V$6 | H13: ='Crewe Alexandra'!$V$7 | I13: ='Crewe Alexandra'!$V$8 | J13: ='Crewe Alexandra'!$V$9 | K13: ='Crewe Alexandra'!$V$10 | L13: ='Crewe Alexandra'!$V$11
A14: Grimsby Town | B14: ='Grimsby Town'!$E$35 | C14: ='Grimsby Town'!$V$2 | D14: ='Grimsby Town'!$V$3 | E14: ='Grimsby Town'!$V$4 | F14: ='Grimsby Town'!$V$5 | G14: ='Grimsby Town'!$V$6 | H14: ='Grimsby Town'!$V$7 | I14: ='Grimsby Town'!$V$8 | J14: ='Grimsby Town'!$V$9 | K14: ='Grimsby Town'!$V$10 | L14: ='Grimsby Town'!$V$11
A15: Barnet | B15: ='Barnet'!$E$33 | C15: ='Barnet'!$V$2 | D15: ='Barnet'!$V$3 | E15: ='Barnet'!$V$4 | F15: ='Barnet'!$V$5 | G15: ='Barnet'!$V$6 | H15: ='Barnet'!$V$7 | I15: ='Barnet'!$V$8 | J15: ='Barnet'!$V$9
A16: Oldham Athletic | B16: ='Oldham Athletic'!$E$34 | C16: ='Oldham Athletic'!$V$2 | D16: ='Oldham Athletic'!$V$3 | E16: ='Oldham Athletic'!$V$4 | F16: ='Oldham Athletic'!$V$5 | G16: ='Oldham Athletic'!$V$6 | H16: ='Oldham Athletic'!$V$7 | I16: ='Oldham Athletic'!$V$8 | J16: ='Oldham Athletic'!$V$9 | K16: ='Oldham Athletic'!$V$10
A17: Tranmere Rovers | B17: ='Tranmere Rovers'!$E$35 | C17: ='Tranmere Rovers'!$V$2 | D17: ='Tranmere Rovers'!$V$3 | E17: ='Tranmere Rovers'!$V$4 | F17: ='Tranmere Rovers'!$V$5 | G17: ='Tranmere Rovers'!$V$6 | H17: ='Tranmere Rovers'!$V$7 | I17: ='Tranmere Rovers'!$V$8 | J17: ='Tranmere Rovers'!$V$9 | K17: ='Tranmere Rovers'!$V$10 | L17: ='Tranmere Rovers'!$V$11
A18: Bristol Rvs | B18: ='Bristol Rvs'!$E$35 | C18: ='Bristol Rvs'!$V$2 | D18: ='Bristol Rvs'!$V$3 | E18: ='Bristol Rvs'!$V$4 | F18: ='Bristol Rvs'!$V$5 | G18: ='Bristol Rvs'!$V$6 | H18: ='Bristol Rvs'!$V$7 | I18: ='Bristol Rvs'!$V$8 | J18: ='Bristol Rvs'!$V$9 | K18: ='Bristol Rvs'!$V$10 | L18: ='Bristol Rvs'!$V$11
A19: Cheltenham Town | B19: ='Cheltenham Town'!$E$35 | C19: ='Cheltenham Town'!$V$2 | D19: ='Cheltenham Town'!$V$3 | E19: ='Cheltenham Town'!$V$4 | F19: ='Cheltenham Town'!$V$5 | G19: ='Cheltenham Town'!$V$6 | H19: ='Cheltenham Town'!$V$7 | I19: ='Cheltenham Town'!$V$8 | J19: ='Cheltenham Town'!$V$9 | K19: ='Cheltenham Town'!$V$10 | L19: ='Cheltenham Town'!$V$11
A20: Swindon Town | B20: ='Swindon Town'!$E$35 | C20: ='Swindon Town'!$V$2 | D20: ='Swindon Town'!$V$3 | E20: ='Swindon Town'!$V$4 | F20: ='Swindon Town'!$V$5 | G20: ='Swindon Town'!$V$6 | H20: ='Swindon Town'!$V$7 | I20: ='Swindon Town'!$V$8 | J20: ='Swindon Town'!$V$9 | K20: ='Swindon Town'!$V$10 | L20: ='Swindon Town'!$V$11
A21: Colchester United | B21: ='Colchester United'!$E$34 | C21: ='Colchester United'!$V$2 | D21: ='Colchester United'!$V$3 | E21: ='Colchester United'!$V$4 | F21: ='Colchester United'!$V$5 | G21: ='Colchester United'!$V$6 | H21: ='Colchester United'!$V$7 | I21: ='Colchester United'!$V$8 | J21: ='Colchester United'!$V$9 | K21: ='Colchester United'!$V$10
A22: Salford City | B22: ='Salford City'!$E$35 | C22: ='Salford City'!$V$2 | D22: ='Salford City'!$V$3 | E22: ='Salford City'!$V$4 | F22: ='Salford City'!$V$5 | G22: ='Salford City'!$V$6 | H22: ='Salford City'!$V$7 | I22: ='Salford City'!$V$8 | J22: ='Salford City'!$V$9 | K22: ='Salford City'!$V$10 | L22: ='Salford City'!$V$11
A23: Fleetwood Town | B23: ='Fleetwood Town'!$E$35 | C23: ='Fleetwood Town'!$V$2 | D23: ='Fleetwood Town'!$V$3 | E23: ='Fleetwood Town'!$V$4 | F23: ='Fleetwood Town'!$V$5 | G23: ='Fleetwood Town'!$V$6 | H23: ='Fleetwood Town'!$V$7 | I23: ='Fleetwood Town'!$V$8 | J23: ='Fleetwood Town'!$V$9 | K23: ='Fleetwood Town'!$V$10 | L23: ='Fleetwood Town'!$V$11
A24: Northampton Town | B24: ='Northampton Town'!$E$33 | C24: ='Northampton Town'!$V$2 | D24: ='Northampton Town'!$V$3 | E24: ='Northampton Town'!$V$4 | F24: ='Northampton Town'!$V$5 | G24: ='Northampton Town'!$V$6 | H24: ='Northampton Town'!$V$7 | I24: ='Northampton Town'!$V$8 | J24: ='Northampton Town'!$V$9
A25: Rochdale | B25: ='Rochdale'!$E$35 | C25: ='Rochdale'!$V$2 | D25: ='Rochdale'!$V$3 | E25: ='Rochdale'!$V$4 | F25: ='Rochdale'!$V$5 | G25: ='Rochdale'!$V$6 | H25: ='Rochdale'!$V$7 | I25: ='Rochdale'!$V$8 | J25: ='Rochdale'!$V$9 | K25: ='Rochdale'!$V$10 | L25: ='Rochdale'!$V$11

Sheet Accrington Stanley
A1: Date | B1: Opponent | C1: Venue | D1: Goals For | E1: Goals Against | F1: xG Pre-Match (For) | G1: xG Pre-Match (Against) | H1: xG Actual (For) | I1: xG Actual (Against) | J1: xG Delta (For) | K1: xG Delta (Against) | L1: Rolling Delta (For) | M1: Rolling Delta (Against) | N1: xG Delta (For, Adj) | O1: xG Delta (Against, Adj) | P1: Rolling Delta (For, Adj) | Q1: Rolling Delta (Against, Adj) | R1: Supremacy Delta | S1: Match Total xG Delta | T1: xPts (Actual) | U1: xPts (Market) | V1: xPts Delta | W1: xPts (Actual, Cum.) | X1: xPts (Market, Cum.)
A2: 2026-08-15 | B2: Colchester United | C2: Home | D2: 2 | E2: 2 | F2: 1.33 | G2: 1.19 | H2: 2.78 | I2: 0.74 | J2: 1.45 | K2: -0.45 | L2: 1.45 | M2: -0.45 | N2: 1.38 | O2: -0.31 | P2: 1.38 | Q2: -0.31 | R2: =(H2-I2)-(F2-G2) | S2: =(H2+I2)-(F2+G2) | T2: 2.52 | U2: 1.47 | V2: 1.05 | W2: 2.52 | X2: 1.47
A3: 2026-08-22 | B3: Exeter | C3: Away | D3: 0 | E3: 2 | F3: 1.06 | G3: 1.58 | H3: 0.68 | I3: 2.31 | J3: -0.38 | K3: 0.73 | L3: 0.53 | M3: 0.14 | N3: -0.03 | O3: 0.81 | P3: 0.67 | Q3: 0.25 | R3: =(H3-I3)-(F3-G3) | S3: =(H3+I3)-(F3+G3) | T3: 0.44 | U3: 1.02 | V3: -0.57 | W3: 2.96 | X3: 2.49
